Workbook

Sheet Notas
B2: MODELO OPERATIVO — PLANTA KOF BOGOTÁ (FONTIBÓN) · DATOS TRIMESTRALES REALES 2021T1–2026T1 · PRONÓSTICO abr-26→mar-27
B4: ■ Procedimiento formal
B5: Sigue el diagrama de flujo del proyecto: análisis de datos → correlación → prueba de rachas → Kruskal-Wallis → Levene → autocorrelación (¿constante/tendencia/estacionalidad?) → ESTACIONALIDAD detectada (ACF lag-12 significativo, Ljung-Box p≈0) → Holt-Winters multiplicativo → error (MAD, CFE, MSE, MAPE) → señal de rastreo → pronóstico.
B7: ■ Modelo
B8: Holt-Winters multiplicativo con tendencia amortiguada (φ<1, Gardner & McKenzie 1985): variante conservadora estándar en industria. Parámetros por máxima verosimilitud (statsmodels): ver hoja Backtest_TS.
B10: ■ Señal de rastreo — hallazgo
B11: En el backtest trimestral la TS toca −4: sesgo por sobre-pronóstico con CAUSA ASIGNABLE = quiebre estructural del impuesto saludable (ene-2025). Es el comportamiento esperado de la señal: detectar el cambio de nivel. El modelo final, reentrenado con 2025 completo (α≈0,98), adapta el nivel y el pronóstico 2026 parte de la base corregida.
B13: ■ Empaque y lotes
B14: Jerarquías reales de planta: P1 cajón×30 → capa 9 cajones → pallet 6 capas = 1.620 bot = 567 L. P2 pack×6 → capa 28 packs → pallet 5 capas = 840 bot = 1.260 L. P3 rack×6 = capa → pallet 5 capas = 30 garrafones = 750 L. La línea libera PALLETS COMPLETOS: lote mínimo e incremento = 1 pallet; lote estándar = demanda mensual/corridas_mes (parámetro de planeación, 20 por defecto; tiempos se estudiarán después).
B16: ■ Rotación
B17: Inventario de ciclo = Lote/2; Rotación = Demanda anual/(Lote/2); Cobertura = 365/Rotación. Se presenta bajo 3 escenarios de lote (diario≈20 corridas/mes, semanal≈4, mensual=1).
B19: ■ ERP (Odoo)
B20: Archivos de importación en erp_odoo/: uom_uom.csv (UdM por jerarquía), product_template.csv (SKU + EAN-13 prefijo 770 Colombia con dígito de control), product_packaging.csv (cajón/pack/rack, capa, pallet), pronostico_ventas.csv (demanda mensual en unidades). Códigos estilo catálogo real Coca-Cola (ref.: 75005771 'Cocacola 355 Ml Ret.', 7501032401917 'Agua Cristal 20lt').

Sheet SKUs_Empaques
B2: MAESTRO DE PRODUCTOS Y JERARQUÍA DE EMPAQUE (base ERP)
B4: SKU | C4: Nombre comercial | D4: EAN-13 | E4: Envase (L) | F4: Und/agrup. | G4: Agrup/capa | H4: Capas/pallet | I4: Und/capa | J4: Und/pallet | K4: L/pallet
B5: CC-RET-350 | C5: Coca-Cola 350 ml Vidrio Retornable | D5: 7701000000016 | E5: 0.35 | F5: 30 | G5: 9 | H5: 6 | I5: =F5*G5 | J5: =I5*H5 | K5: =J5*E5
B6: QT-NR-1500 | C6: QuAtro Toronja 1.5 L PET No Retornable | D6: 7701000000023 | E6: 1.5 | F6: 6 | G6: 28 | H6: 5 | I6: =F6*G6 | J6: =I6*H6 | K6: =J6*E6
B7: AG-GF-25000 | C7: Garrafón Agua 25 L Retornable | D7: 7701000000030 | E7: 25 | F7: 6 | G7: 1 | H7: 5 | I7: =F7*G7 | J7: =I7*H7 | K7: =J7*E7
B9: Agrupación: P1=cajón, P2=pack, P3=rack (rack=capa). Lote mínimo/incremento de producción = 1 pallet (la línea libera pallets completos).

Sheet Pruebas
B2: ANÁLISIS ESTADÍSTICO FORMAL (ruta del diagrama de flujo)
B4: Categoría (dato real KOF) | C4: Rachas p | D4: Kruskal-Wallis p | E4: Levene p | F4: ACF lag-4 (Δserie) | G4: Ljung-Box p | H4: ¿Estacional?
B5: refrescos | C5: 0.5076 | D5: 0.27 | E5: 0.2499 | F5: 0.493 | G5: 0.027915 | H5: SÍ
B6: agua | C6: 0.0008 | D6: 0.0076 | E6: 0.0047 | F6: 0.252 | G6: 0.456111 | H6: NO
B7: garrafon | C7: 0.5076 | D7: 0.0066 | E7: 0.9798 | F7: 0.039 | G7: 0.64177 | H7: NO
B9: Conclusión: Serie trimestral REAL (21 obs.): sobre la serie DIFERENCIADA (sin tendencia), el ACF en rezago 4 es significativo -> estacionalidad anual confirmada con datos observados. Kruskal-Wallis detecta diferencias de nivel entre anios (crecimiento 2021-2024, quiebre 2025). Ruta del diagrama: Holt-Winters multiplicativo, m=4 (trimestral).

Sheet Pronostico_2026
B2: PRONÓSTICO abr-2026 → mar-2027 → UNIDADES → EMPAQUE → PALLETS → LOTE (por producto)
B3: Litros = salida Holt-Winters (valores). Conversiones = fórmulas enlazadas a SKUs_Empaques. Lote estándar = ROUNDUP(pallets/corridas,0).
B4: Corridas/mes: | C4: 20
B6: P1 — Coca-Cola 350 ml Vidrio Retornable
B7: Mes | C7: Litros | D7: Unidades | E7: Cajones | F7: Capas | G7: Pallets | H7: Lote est. (pallets) | I7: Lote est. (und)
B8: Abr-26 | C8: 5068102 | D8: =C8/SKUs_Empaques!$E$5 | E8: =ROUNDUP(D8/SKUs_Empaques!$F$5,0) | F8: =ROUNDUP(D8/SKUs_Empaques!$I$5,0) | G8: =ROUNDUP(D8/SKUs_Empaques!$J$5,0) | H8: =MAX(1,ROUNDUP(G8/$C$4,0)) | I8: =H8*SKUs_Empaques!$J$5
B9: May-26 | C9: 5225009 | D9: =C9/SKUs_Empaques!$E$5 | E9: =ROUNDUP(D9/SKUs_Empaques!$F$5,0) | F9: =ROUNDUP(D9/SKUs_Empaques!$I$5,0) | G9: =ROUNDUP(D9/SKUs_Empaques!$J$5,0) | H9: =MAX(1,ROUNDUP(G9/$C$4,0)) | I9: =H9*SKUs_Empaques!$J$5
B10: Jun-26 | C10: 5381916 | D10: =C10/SKUs_Empaques!$E$5 | E10: =ROUNDUP(D10/SKUs_Empaques!$F$5,0) | F10: =ROUNDUP(D10/SKUs_Empaques!$I$5,0) | G10: =ROUNDUP(D10/SKUs_Empaques!$J$5,0) | H10: =MAX(1,ROUNDUP(G10/$C$4,0)) | I10: =H10*SKUs_Empaques!$J$5
B11: Jul-26 | C11: 5700836 | D11: =C11/SKUs_Empaques!$E$5 | E11: =ROUNDUP(D11/SKUs_Empaques!$F$5,0) | F11: =ROUNDUP(D11/SKUs_Empaques!$I$5,0) | G11: =ROUNDUP(D11/SKUs_Empaques!$J$5,0) | H11: =MAX(1,ROUNDUP(G11/$C$4,0)) | I11: =H11*SKUs_Empaques!$J$5
B12: Ago-26 | C12: 5374141 | D12: =C12/SKUs_Empaques!$E$5 | E12: =ROUNDUP(D12/SKUs_Empaques!$F$5,0) | F12: =ROUNDUP(D12/SKUs_Empaques!$I$5,0) | G12: =ROUNDUP(D12/SKUs_Empaques!$J$5,0) | H12: =MAX(1,ROUNDUP(G12/$C$4,0)) | I12: =H12*SKUs_Empaques!$J$5
B13: Sep-26 | C13: 5259798 | D13: =C13/SKUs_Empaques!$E$5 | E13: =ROUNDUP(D13/SKUs_Empaques!$F$5,0) | F13: =ROUNDUP(D13/SKUs_Empaques!$I$5,0) | G13: =ROUNDUP(D13/SKUs_Empaques!$J$5,0) | H13: =MAX(1,ROUNDUP(G13/$C$4,0)) | I13: =H13*SKUs_Empaques!$J$5
B14: Oct-26 | C14: 5410606 | D14: =C14/SKUs_Empaques!$E$5 | E14: =ROUNDUP(D14/SKUs_Empaques!$F$5,0) | F14: =ROUNDUP(D14/SKUs_Empaques!$I$5,0) | G14: =ROUNDUP(D14/SKUs_Empaques!$J$5,0) | H14: =MAX(1,ROUNDUP(G14/$C$4,0)) | I14: =H14*SKUs_Empaques!$J$5
B15: Nov-26 | C15: 5690767 | D15: =C15/SKUs_Empaques!$E$5 | E15: =ROUNDUP(D15/SKUs_Empaques!$F$5,0) | F15: =ROUNDUP(D15/SKUs_Empaques!$I$5,0) | G15: =ROUNDUP(D15/SKUs_Empaques!$J$5,0) | H15: =MAX(1,ROUNDUP(G15/$C$4,0)) | I15: =H15*SKUs_Empaques!$J$5
B16: Dic-26 | C16: 6408679 | D16: =C16/SKUs_Empaques!$E$5 | E16: =ROUNDUP(D16/SKUs_Empaques!$F$5,0) | F16: =ROUNDUP(D16/SKUs_Empaques!$I$5,0) | G16: =ROUNDUP(D16/SKUs_Empaques!$J$5,0) | H16: =MAX(1,ROUNDUP(G16/$C$4,0)) | I16: =H16*SKUs_Empaques!$J$5
B17: Ene-27 | C17: 5362943 | D17: =C17/SKUs_Empaques!$E$5 | E17: =ROUNDUP(D17/SKUs_Empaques!$F$5,0) | F17: =ROUNDUP(D17/SKUs_Empaques!$I$5,0) | G17: =ROUNDUP(D17/SKUs_Empaques!$J$5,0) | H17: =MAX(1,ROUNDUP(G17/$C$4,0)) | I17: =H17*SKUs_Empaques!$J$5
B18: Feb-27 | C18: 5012840 | D18: =C18/SKUs_Empaques!$E$5 | E18: =ROUNDUP(D18/SKUs_Empaques!$F$5,0) | F18: =ROUNDUP(D18/SKUs_Empaques!$I$5,0) | G18: =ROUNDUP(D18/SKUs_Empaques!$J$5,0) | H18: =MAX(1,ROUNDUP(G18/$C$4,0)) | I18: =H18*SKUs_Empaques!$J$5
B19: Mar-27 | C19: 5537994 | D19: =C19/SKUs_Empaques!$E$5 | E19: =ROUNDUP(D19/SKUs_Empaques!$F$5,0) | F19: =ROUNDUP(D19/SKUs_Empaques!$I$5,0) | G19: =ROUNDUP(D19/SKUs_Empaques!$J$5,0) | H19: =MAX(1,ROUNDUP(G19/$C$4,0)) | I19: =H19*SKUs_Empaques!$J$5
B20: TOTAL | C20: =SUM(C8:C19) | D20: =SUM(D8:D19) | E20: =SUM(E8:E19) | F20: =SUM(F8:F19) | G20: =SUM(G8:G19)
B22: P2 — QuAtro Toronja 1.5 L PET No Retornable
B23: Mes | C23: Litros | D23: Unidades | E23: Packs | F23: Capas | G23: Pallets | H23: Lote est. (pallets) | I23: Lote est. (und)
B24: Abr-26 | C24: 6324481 | D24: =C24/SKUs_Empaques!$E$6 | E24: =ROUNDUP(D24/SKUs_Empaques!$F$6,0) | F24: =ROUNDUP(D24/SKUs_Empaques!$I$6,0) | G24: =ROUNDUP(D24/SKUs_Empaques!$J$6,0) | H24: =MAX(1,ROUNDUP(G24/$C$4,0)) | I24: =H24*SKUs_Empaques!$J$6
B25: May-26 | C25: 6520286 | D25: =C25/SKUs_Empaques!$E$6 | E25: =ROUNDUP(D25/SKUs_Empaques!$F$6,0) | F25: =ROUNDUP(D25/SKUs_Empaques!$I$6,0) | G25: =ROUNDUP(D25/SKUs_Empaques!$J$6,0) | H25: =MAX(1,ROUNDUP(G25/$C$4,0)) | I25: =H25*SKUs_Empaques!$J$6
B26: Jun-26 | C26: 6716090 | D26: =C26/SKUs_Empaques!$E$6 | E26: =ROUNDUP(D26/SKUs_Empaques!$F$6,0) | F26: =ROUNDUP(D26/SKUs_Empaques!$I$6,0) | G26: =ROUNDUP(D26/SKUs_Empaques!$J$6,0) | H26: =MAX(1,ROUNDUP(G26/$C$4,0)) | I26: =H26*SKUs_Empaques!$J$6
B27: Jul-26 | C27: 7114068 | D27: =C27/SKUs_Empaques!$E$6 | E27: =ROUNDUP(D27/SKUs_Empaques!$F$6,0) | F27: =ROUNDUP(D27/SKUs_Empaques!$I$6,0) | G27: =ROUNDUP(D27/SKUs_Empaques!$J$6,0) | H27: =MAX(1,ROUNDUP(G27/$C$4,0)) | I27: =H27*SKUs_Empaques!$J$6
B28: Ago-26 | C28: 6706385 | D28: =C28/SKUs_Empaques!$E$6 | E28: =ROUNDUP(D28/SKUs_Empaques!$F$6,0) | F28: =ROUNDUP(D28/SKUs_Empaques!$I$6,0) | G28: =ROUNDUP(D28/SKUs_Empaques!$J$6,0) | H28: =MAX(1,ROUNDUP(G28/$C$4,0)) | I28: =H28*SKUs_Empaques!$J$6
B29: Sep-26 | C29: 6563696 | D29: =C29/SKUs_Empaques!$E$6 | E29: =ROUNDUP(D29/SKUs_Empaques!$F$6,0) | F29: =ROUNDUP(D29/SKUs_Empaques!$I$6,0) | G29: =ROUNDUP(D29/SKUs_Empaques!$J$6,0) | H29: =MAX(1,ROUNDUP(G29/$C$4,0)) | I29: =H29*SKUs_Empaques!$J$6
B30: Oct-26 | C30: 6751887 | D30: =C30/SKUs_Empaques!$E$6 | E30: =ROUNDUP(D30/SKUs_Empaques!$F$6,0) | F30: =ROUNDUP(D30/SKUs_Empaques!$I$6,0) | G30: =ROUNDUP(D30/SKUs_Empaques!$J$6,0) | H30: =MAX(1,ROUNDUP(G30/$C$4,0)) | I30: =H30*SKUs_Empaques!$J$6
B31: Nov-26 | C31: 7101500 | D31: =C31/SKUs_Empaques!$E$6 | E31: =ROUNDUP(D31/SKUs_Empaques!$F$6,0) | F31: =ROUNDUP(D31/SKUs_Empaques!$I$6,0) | G31: =ROUNDUP(D31/SKUs_Empaques!$J$6,0) | H31: =MAX(1,ROUNDUP(G31/$C$4,0)) | I31: =H31*SKUs_Empaques!$J$6
B32: Dic-26 | C32: 7997381 | D32: =C32/SKUs_Empaques!$E$6 | E32: =ROUNDUP(D32/SKUs_Empaques!$F$6,0) | F32: =ROUNDUP(D32/SKUs_Empaques!$I$6,0) | G32: =ROUNDUP(D32/SKUs_Empaques!$J$6,0) | H32: =MAX(1,ROUNDUP(G32/$C$4,0)) | I32: =H32*SKUs_Empaques!$J$6
B33: Ene-27 | C33: 6692410 | D33: =C33/SKUs_Empaques!$E$6 | E33: =ROUNDUP(D33/SKUs_Empaques!$F$6,0) | F33: =ROUNDUP(D33/SKUs_Empaques!$I$6,0) | G33: =ROUNDUP(D33/SKUs_Empaques!$J$6,0) | H33: =MAX(1,ROUNDUP(G33/$C$4,0)) | I33: =H33*SKUs_Empaques!$J$6
B34: Feb-27 | C34: 6255516 | D34: =C34/SKUs_Empaques!$E$6 | E34: =ROUNDUP(D34/SKUs_Empaques!$F$6,0) | F34: =ROUNDUP(D34/SKUs_Empaques!$I$6,0) | G34: =ROUNDUP(D34/SKUs_Empaques!$J$6,0) | H34: =MAX(1,ROUNDUP(G34/$C$4,0)) | I34: =H34*SKUs_Empaques!$J$6
B35: Mar-27 | C35: 6910856 | D35: =C35/SKUs_Empaques!$E$6 | E35: =ROUNDUP(D35/SKUs_Empaques!$F$6,0) | F35: =ROUNDUP(D35/SKUs_Empaques!$I$6,0) | G35: =ROUNDUP(D35/SKUs_Empaques!$J$6,0) | H35: =MAX(1,ROUNDUP(G35/$C$4,0)) | I35: =H35*SKUs_Empaques!$J$6
B36: TOTAL | C36: =SUM(C24:C35) | D36: =SUM(D24:D35) | E36: =SUM(E24:E35) | F36: =SUM(F24:F35) | G36: =SUM(G24:G35)
B38: P3 — Garrafón Agua 25 L Retornable
B39: Mes | C39: Litros | D39: Unidades | E39: Racks | F39: Capas | G39: Pallets | H39: Lote est. (pallets) | I39: Lote est. (und)
B40: Abr-26 | C40: 536539 | D40: =C40/SKUs_Empaques!$E$7 | E40: =ROUNDUP(D40/SKUs_Empaques!$F$7,0) | F40: =ROUNDUP(D40/SKUs_Empaques!$I$7,0) | G40: =ROUNDUP(D40/SKUs_Empaques!$J$7,0) | H40: =MAX(1,ROUNDUP(G40/$C$4,0)) | I40: =H40*SKUs_Empaques!$J$7
B41: May-26 | C41: 553150 | D41: =C41/SKUs_Empaques!$E$7 | E41: =ROUNDUP(D41/SKUs_Empaques!$F$7,0) | F41: =ROUNDUP(D41/SKUs_Empaques!$I$7,0) | G41: =ROUNDUP(D41/SKUs_Empaques!$J$7,0) | H41: =MAX(1,ROUNDUP(G41/$C$4,0)) | I41: =H41*SKUs_Empaques!$J$7
B42: Jun-26 | C42: 569761 | D42: =C42/SKUs_Empaques!$E$7 | E42: =ROUNDUP(D42/SKUs_Empaques!$F$7,0) | F42: =ROUNDUP(D42/SKUs_Empaques!$I$7,0) | G42: =ROUNDUP(D42/SKUs_Empaques!$J$7,0) | H42: =MAX(1,ROUNDUP(G42/$C$4,0)) | I42: =H42*SKUs_Empaques!$J$7
B43: Jul-26 | C43: 627602 | D43: =C43/SKUs_Empaques!$E$7 | E43: =ROUNDUP(D43/SKUs_Empaques!$F$7,0) | F43: =ROUNDUP(D43/SKUs_Empaques!$I$7,0) | G43: =ROUNDUP(D43/SKUs_Empaques!$J$7,0) | H43: =MAX(1,ROUNDUP(G43/$C$4,0)) | I43: =H43*SKUs_Empaques!$J$7
B44: Ago-26 | C44: 591636 | D44: =C44/SKUs_Empaques!$E$7 | E44: =ROUNDUP(D44/SKUs_Empaques!$F$7,0) | F44: =ROUNDUP(D44/SKUs_Empaques!$I$7,0) | G44: =ROUNDUP(D44/SKUs_Empaques!$J$7,0) | H44: =MAX(1,ROUNDUP(G44/$C$4,0)) | I44: =H44*SKUs_Empaques!$J$7
...

Sheet Backtest_TS
B2: EVALUACIÓN DEL ERROR Y SEÑAL DE RASTREO (backtest trimestral: entrena 2021T1–2024T4, prueba 2025T1–2026T1 reales)
B4: Prod. | C4: Trim. | D4: Real (L) | E4: Pronóstico (L) | F4: Error (L) | G4: CFE | H4: MAD | I4: TS=CFE/MAD | J4: |TS|≤4
B5: P1 | C5: 2025T1 | D5: 14174737 | E5: 15171089 | F5: =D5-E5 | G5: =SUM($F$5:F5) | H5: =SUMPRODUCT(ABS($F$5:F5))/(ROW(F5)-ROW($F$5)+1) | I5: =G5/H5 | J5: =IF(ABS(I5)<=4,"SI","NO")
B6: P1 | C6: 2025T2 | D6: 14588262 | E6: 15282484 | F6: =D6-E6 | G6: =SUM($F$5:F6) | H6: =SUMPRODUCT(ABS($F$5:F6))/(ROW(F6)-ROW($F$5)+1) | I6: =G6/H6 | J6: =IF(ABS(I6)<=4,"SI","NO")
B7: P1 | C7: 2025T3 | D7: 15759918 | E7: 15763945 | F7: =D7-E7 | G7: =SUM($F$5:F7) | H7: =SUMPRODUCT(ABS($F$5:F7))/(ROW(F7)-ROW($F$5)+1) | I7: =G7/H7 | J7: =IF(ABS(I7)<=4,"SI","NO")
B8: P1 | C8: 2025T4 | D8: 17046442 | E8: 16847740 | F8: =D8-E8 | G8: =SUM($F$5:F8) | H8: =SUMPRODUCT(ABS($F$5:F8))/(ROW(F8)-ROW($F$5)+1) | I8: =G8/H8 | J8: =IF(ABS(I8)<=4,"SI","NO")
B9: P1 | C9: 2026T1 | D9: 15484234 | E9: 15579574 | F9: =D9-E9 | G9: =SUM($F$5:F9) | H9: =SUMPRODUCT(ABS($F$5:F9))/(ROW(F9)-ROW($F$5)+1) | I9: =G9/H9 | J9: =IF(ABS(I9)<=4,"SI","NO")
B10: P2 | C10: 2025T1 | D10: 17688642 | E10: 18931992 | F10: =D10-E10 | G10: =SUM($F$10:F10) | H10: =SUMPRODUCT(ABS($F$10:F10))/(ROW(F10)-ROW($F$10)+1) | I10: =G10/H10 | J10: =IF(ABS(I10)<=4,"SI","NO")
B11: P2 | C11: 2025T2 | D11: 18204680 | E11: 19071001 | F11: =D11-E11 | G11: =SUM($F$10:F11) | H11: =SUMPRODUCT(ABS($F$10:F11))/(ROW(F11)-ROW($F$10)+1) | I11: =G11/H11 | J11: =IF(ABS(I11)<=4,"SI","NO")
B12: P2 | C12: 2025T3 | D12: 19666788 | E12: 19671817 | F12: =D12-E12 | G12: =SUM($F$10:F12) | H12: =SUMPRODUCT(ABS($F$10:F12))/(ROW(F12)-ROW($F$10)+1) | I12: =G12/H12 | J12: =IF(ABS(I12)<=4,"SI","NO")
B13: P2 | C13: 2025T4 | D13: 21272240 | E13: 21024278 | F13: =D13-E13 | G13: =SUM($F$10:F13) | H13: =SUMPRODUCT(ABS($F$10:F13))/(ROW(F13)-ROW($F$10)+1) | I13: =G13/H13 | J13: =IF(ABS(I13)<=4,"SI","NO")
B14: P2 | C14: 2026T1 | D14: 19322763 | E14: 19441738 | F14: =D14-E14 | G14: =SUM($F$10:F14) | H14: =SUMPRODUCT(ABS($F$10:F14))/(ROW(F14)-ROW($F$10)+1) | I14: =G14/H14 | J14: =IF(ABS(I14)<=4,"SI","NO")
B15: P3 | C15: 2025T1 | D15: 1689238 | E15: 1806956 | F15: =D15-E15 | G15: =SUM($F$15:F15) | H15: =SUMPRODUCT(ABS($F$15:F15))/(ROW(F15)-ROW($F$15)+1) | I15: =G15/H15 | J15: =IF(ABS(I15)<=4,"SI","NO")
B16: P3 | C16: 2025T2 | D16: 1689238 | E16: 1746961 | F16: =D16-E16 | G16: =SUM($F$15:F16) | H16: =SUMPRODUCT(ABS($F$15:F16))/(ROW(F16)-ROW($F$15)+1) | I16: =G16/H16 | J16: =IF(ABS(I16)<=4,"SI","NO")
B17: P3 | C17: 2025T3 | D17: 1834030 | E17: 1896792 | F17: =D17-E17 | G17: =SUM($F$15:F17) | H17: =SUMPRODUCT(ABS($F$15:F17))/(ROW(F17)-ROW($F$15)+1) | I17: =G17/H17 | J17: =IF(ABS(I17)<=4,"SI","NO")
B18: P3 | C18: 2025T4 | D18: 1785766 | E18: 1855033 | F18: =D18-E18 | G18: =SUM($F$15:F18) | H18: =SUMPRODUCT(ABS($F$15:F18))/(ROW(F18)-ROW($F$15)+1) | I18: =G18/H18 | J18: =IF(ABS(I18)<=4,"SI","NO")
B19: P3 | C19: 2026T1 | D19: 1737502 | E19: 1828063 | F19: =D19-E19 | G19: =SUM($F$15:F19) | H19: =SUMPRODUCT(ABS($F$15:F19))/(ROW(F19)-ROW($F$15)+1) | I19: =G19/H19 | J19: =IF(ABS(I19)<=4,"SI","NO")
B21: Prod. | C21: MAD (L) | D21: CFE (L) | E21: MSE | F21: RMSE (L) | G21: MAPE % | H21: TS final | I21: α | J21: φ
B22: P1 | C22: 397729 | D22: -1591241 | E22: 304650304880 | F22: 551951 | G22: 2.72 | H22: -4 | I22: 0.9456 | J22: 0.988
B23: P2 | C23: 496328 | D23: -1985713 | E23: 474419337918 | F23: 688781 | G23: 2.72 | H23: -4 | I23: 0.9456 | J23: 0.988
B24: P3 (combo directo+agua) | C24: 79606 | D24: -398031 | E24: 6825542267 | F24: 82617 | G24: 4.58 | H24: -5 | I24: 1 | J24: 0.8
B26: Lectura: MAPE 1,9–2,7% trimestral (excelente); validación un-paso 2026T1: +0,07% P1/P2, +0,47% P3. TS<−4 con causa asignable: quiebre estructural del impuesto saludable en 2025 no observable desde 2022–2024. El modelo de producción, reentrenado con 2025 (α≈0,98), parte del nivel corregido; la señal debe monitorearse mensualmente en operación.

Sheet Rotacion
B2: ROTACIÓN DE INVENTARIOS — lote base = producción de un TURNO
B3: Rotación = Demanda anual ÷ (Lote/2). Cobertura = 365 ÷ Rotación. Escenarios: corrida diaria (≈20/mes), semanal (≈4/mes), mensual (1/mes).
B5: Prod. | C5: Und/pallet | D5: Demanda anual (und) | E5: Demanda (pallets) | F5: Lote TURNO (pal) | G5: Rot. turno | H5: Cob. días | I5: Lote día 2T (pal) | J5: Rot. día | K5: Lote semanal (pal) | L5: Rot. semanal
B6: P1 | C6: =SKUs_Empaques!$J$5 | D6: 186953224 | E6: 115409 | F6: 162 | G6: =D6/((F6*C6)/2) | H6: =365/G6 | I6: 324 | J6: =D6/((I6*C6)/2) | K6: 1944 | L6: =D6/((K6*C6)/2)
B7: P2 | C7: =SKUs_Empaques!$J$6 | D7: 54436369 | E7: 64812 | F7: 87 | G7: =D7/((F7*C7)/2) | H7: =365/G7 | I7: 174 | J7: =D7/((I7*C7)/2) | K7: 1044 | L7: =D7/((K7*C7)/2)
B8: P3 | C8: =SKUs_Empaques!$J$7 | D8: 277572 | E8: 9259 | F8: 96 | G8: =D8/((F8*C8)/2) | H8: =365/G8 | I8: 192 | J8: =D8/((I8*C8)/2) | K8: 1152 | L8: =D8/((K8*C8)/2)

Sheet Escenarios
B2: ESCENARIOS DE DEMANDA — factores que suben o bajan el pronóstico base
B3: 1) Elija un escenario de referencia abajo y copie sus 12 factores a la fila 'FACTOR ACTIVO' de cada producto (o escriba los suyos: es libre). 2) El pronóstico AJUSTADO se recalcula solo. 3) 'Personalizado' = escriba directamente, sin copiar nada.
B5: TABLA DE REFERENCIA — presets documentados (ver Referencias / data/escenarios_resumen.csv)
B6: Preset — P1
B7: Escenario | C7: Abr | D7: May | E7: Jun | F7: Jul | G7: Ago | H7: Sep | I7: Oct | J7: Nov | K7: Dic | L7: Ene | M7: Feb | N7: Mar
B8: Base | C8: 1 | D8: 1 | E8: 1 | F8: 1 | G8: 1 | H8: 1 | I8: 1 | J8: 1 | K8: 1 | L8: 1 | M8: 1 | N8: 1
B9: Mundial 2026 | C9: 1 | D9: 1 | E9: 1.06 | F9: 1.1 | G9: 1.02 | H9: 1 | I9: 1 | J9: 1 | K9: 1 | L9: 1 | M9: 1 | N9: 1
B10: Paro nacional / choque logistico | C10: 1 | D10: 1 | E10: 1 | F10: 1 | G10: 0.82 | H10: 1 | I10: 1.04 | J10: 1 | K10: 1 | L10: 1 | M10: 1 | N10: 1
B11: Recesion moderada | C11: 1 | D11: 1 | E11: 0.95 | F11: 0.95 | G11: 0.95 | H11: 0.95 | I11: 0.95 | J11: 0.95 | K11: 0.95 | L11: 0.95 | M11: 0.95 | N11: 0.95
B12: Restriccion hidrica adicional (CAR) | C12: 1 | D12: 1 | E12: 1 | F12: 1 | G12: 1 | H12: 1 | I12: 1 | J12: 1 | K12: 1 | L12: 1 | M12: 1 | N12: 1
B13: Repunte agresivo post-impuesto | C13: 1.05 | D13: 1.05 | E13: 1.05 | F13: 1.05 | G13: 1.05 | H13: 1.05 | I13: 1.05 | J13: 1.05 | K13: 1.05 | L13: 1.05 | M13: 1.05 | N13: 1.05
B15: Preset — P2
B16: Escenario | C16: Abr | D16: May | E16: Jun | F16: Jul | G16: Ago | H16: Sep | I16: Oct | J16: Nov | K16: Dic | L16: Ene | M16: Feb | N16: Mar
B17: Base | C17: 1 | D17: 1 | E17: 1 | F17: 1 | G17: 1 | H17: 1 | I17: 1 | J17: 1 | K17: 1 | L17: 1 | M17: 1 | N17: 1
B18: Mundial 2026 | C18: 1 | D18: 1 | E18: 1.06 | F18: 1.1 | G18: 1.02 | H18: 1 | I18: 1 | J18: 1 | K18: 1 | L18: 1 | M18: 1 | N18: 1
B19: Paro nacional / choque logistico | C19: 1 | D19: 1 | E19: 1 | F19: 1 | G19: 0.82 | H19: 1 | I19: 1.04 | J19: 1 | K19: 1 | L19: 1 | M19: 1 | N19: 1
B20: Recesion moderada | C20: 1 | D20: 1 | E20: 0.95 | F20: 0.95 | G20: 0.95 | H20: 0.95 | I20: 0.95 | J20: 0.95 | K20: 0.95 | L20: 0.95 | M20: 0.95 | N20: 0.95
B21: Restriccion hidrica adicional (CAR) | C21: 1 | D21: 1 | E21: 1 | F21: 1 | G21: 1 | H21: 1 | I21: 1 | J21: 1 | K21: 1 | L21: 1 | M21: 1 | N21: 1
B22: Repunte agresivo post-impuesto | C22: 1.05 | D22: 1.05 | E22: 1.05 | F22: 1.05 | G22: 1.05 | H22: 1.05 | I22: 1.05 | J22: 1.05 | K22: 1.05 | L22: 1.05 | M22: 1.05 | N22: 1.05
B24: Preset — P3
B25: Escenario | C25: Abr | D25: May | E25: Jun | F25: Jul | G25: Ago | H25: Sep | I25: Oct | J25: Nov | K25: Dic | L25: Ene | M25: Feb | N25: Mar
B26: Base | C26: 1 | D26: 1 | E26: 1 | F26: 1 | G26: 1 | H26: 1 | I26: 1 | J26: 1 | K26: 1 | L26: 1 | M26: 1 | N26: 1
B27: Mundial 2026 | C27: 1 | D27: 1 | E27: 1.01 | F27: 1.02 | G27: 1 | H27: 1 | I27: 1 | J27: 1 | K27: 1 | L27: 1 | M27: 1 | N27: 1
B28: Paro nacional / choque logistico | C28: 1 | D28: 1 | E28: 1 | F28: 1 | G28: 0.82 | H28: 1 | I28: 1.04 | J28: 1 | K28: 1 | L28: 1 | M28: 1 | N28: 1
B29: Recesion moderada | C29: 1 | D29: 1 | E29: 0.98 | F29: 0.98 | G29: 0.98 | H29: 0.98 | I29: 0.98 | J29: 0.98 | K29: 0.98 | L29: 0.98 | M29: 0.98 | N29: 0.98
B30: Restriccion hidrica adicional (CAR) | C30: 1 | D30: 1 | E30: 1 | F30: 0.85 | G30: 0.85 | H30: 0.85 | I30: 0.85 | J30: 0.85 | K30: 0.85 | L30: 0.85 | M30: 0.85 | N30: 0.85
B31: Repunte agresivo post-impuesto | C31: 1 | D31: 1 | E31: 1 | F31: 1 | G31: 1 | H31: 1 | I31: 1 | J31: 1 | K31: 1 | L31: 1 | M31: 1 | N31: 1
B33: ESCENARIO ACTIVO — edite aquí (copie un preset de arriba o escriba su propio factor)
B34: P1 — factor activo
B35: Fila | C35: Abr | D35: May | E35: Jun | F35: Jul | G35: Ago | H35: Sep | I35: Oct | J35: Nov | K35: Dic | L35: Ene | M35: Feb | N35: Mar
B36: FACTOR ACTIVO | C36: 1 | D36: 1 | E36: 1 | F36: 1 | G36: 1 | H36: 1 | I36: 1 | J36: 1 | K36: 1 | L36: 1 | M36: 1 | N36: 1
B37: Litros BASE (Pronóstico) | C37: =Pronostico_2026!C8 | D37: =Pronostico_2026!C9 | E37: =Pronostico_2026!C10 | F37: =Pronostico_2026!C11 | G37: =Pronostico_2026!C12 | H37: =Pronostico_2026!C13 | I37: =Pronostico_2026!C14 | J37: =Pronostico_2026!C15 | K37: =Pronostico_2026!C16 | L37: =Pronostico_2026!C17 | M37: =Pronostico_2026!C18 | N37: =Pronostico_2026!C19
B38: Litros AJUSTADO = base × factor | C38: =C37*C36 | D38: =D37*D36 | E38: =E37*E36 | F38: =F37*F36 | G38: =G37*G36 | H38: =H37*H36 | I38: =I37*I36 | J38: =J37*J36 | ... N38: =N37*N36
B39: Δ % vs base | C39: =C38/C37-1 | D39: =D38/D37-1 | E39: =E38/E37-1 | F39: =F38/F37-1 | G39: =G38/G37-1 | H39: =H38/H37-1 | I39: =I38/I37-1 | J39: =J38/J37-1 | ... N39: =N38/N37-1
B40: TOTAL AÑO (litros) | C40: =SUM(C38:N38) | D40: vs base: | E40: =SUM(C37:N37) | F40: =C40/E40-1
B42: P2 — factor activo
B43: Fila | C43: Abr | D43: May | E43: Jun | F43: Jul | G43: Ago | H43: Sep | I43: Oct | J43: Nov | K43: Dic | L43: Ene | M43: Feb | N43: Mar
B44: FACTOR ACTIVO | C44: 1 | D44: 1 | E44: 1 | F44: 1 | G44: 1 | H44: 1 | I44: 1 | J44: 1 | K44: 1 | L44: 1 | M44: 1 | N44: 1
B45: Litros BASE (Pronóstico) | C45: =Pronostico_2026!C24 | D45: =Pronostico_2026!C25 | E45: =Pronostico_2026!C26 | F45: =Pronostico_2026!C27 | G45: =Pronostico_2026!C28 | H45: =Pronostico_2026!C29 | I45: =Pronostico_2026!C30 | J45: =Pronostico_2026!C31 | K45: =Pronostico_2026!C32 | L45: =Pronostico_2026!C33 | M45: =Pronostico_2026!C34 | N45: =Pronostico_2026!C35
B46: Litros AJUSTADO = base × factor | C46: =C45*C44 | D46: =D45*D44 | E46: =E45*E44 | F46: =F45*F44 | G46: =G45*G44 | H46: =H45*H44 | I46: =I45*I44 | J46: =J45*J44 | ... N46: =N45*N44
...
