Workbook

Sheet Dashboard
A1: DASHBOARD — RESUMEN EJECUTIVO ULOGIX × FEMSA/INDEGA FONTIBÓN
A2: Resumen vivo: demanda desde Demanda; capacidad/OEE desde Tiempos; caso de negocio desde las formulas nativas de Flujo_Caja/CAPEX; nomina desde RRHH. Las metricas MAPE siguen siendo resultados del backtest Python y se actualizan al volver a publicar el pronostico.
A4: ① DEMANDA (pronóstico Base, próximos 12 meses)
A5: producto | B5: demanda anual (und) | C5: MAPE backtest
A6: P1-CC350-RGB | B6: =SUM(Demanda!D$5:D$16) -> 188337814 | C6: 2.9%
A7: P2-QT1500-PET | B7: =SUM(Demanda!E$5:E$16) -> 54228683 | C7: 2.9%
A8: P3-GARR25L | B8: =SUM(Demanda!F$5:F$16) -> 279149 | C8: 2.1%
A10: ② CAPACIDAD Y OEE — ANTES vs. DESPUÉS DEL PROYECTO
A11: línea | B11: OEE antes → después | C11: utilización antes → después | D11: capacidad antes → después | E11: dictamen antes | F11: dictamen después
A12: L1 | B12: =TEXT(Tiempos!I104,"0.0%")&" → "&TEXT(Tiempos!J104,"0.0%") -> 77,1% → 81,0% | C12: =TEXT(Tiempos!U104,"0%")&" → "&TEXT(Tiempos!V104,"0%") -> 126% → 77% | D12: =TEXT(Tiempos!R104/1000000,"0.0")&"M → "&TEXT(Tiempos!T104/1000000,"0.0")&"M" -> 150,0M → 244,5M | E12: =Tiempos!X104 -> INFACTIBLE | F12: =Tiempos!Y104 -> Factible
A13: L2 | B13: =TEXT(Tiempos!I105,"0.0%")&" → "&TEXT(Tiempos!J105,"0.0%") -> 76,5% → 80,3% | C13: =TEXT(Tiempos!U105,"0%")&" → "&TEXT(Tiempos!V105,"0%") -> 129% → 55% | D13: =TEXT(Tiempos!R105/1000000,"0.0")&"M → "&TEXT(Tiempos!T105/1000000,"0.0")&"M" -> 42,0M → 99,2M | E13: =Tiempos!X105 -> INFACTIBLE | F13: =Tiempos!Y105 -> Factible
A14: L3 | B14: =TEXT(Tiempos!I106,"0.0%")&" → "&TEXT(Tiempos!J106,"0.0%") -> 75,4% → 79,1% | C14: =TEXT(Tiempos!U106,"0%")&" → "&TEXT(Tiempos!V106,"0%") -> 80% → 61% | D14: =TEXT(Tiempos!R106/1000000,"0.0")&"M → "&TEXT(Tiempos!T106/1000000,"0.0")&"M" -> 0,3M → 0,5M | E14: =Tiempos!X106 -> Factible | F14: =Tiempos!Y106 -> Factible
A16: ③ CASO DE NEGOCIO (modelo nativo vivo de Sheets)
A17: CAPEX total | B17: {=INDEX(CAPEX!$G:$G,MATCH("CAPEX TOTAL (con contingencia)",CAPEX!$C:$C,0))} -> 9165554245
A18: VPN | B18: =Flujo_Caja!B19 -> 11032069063
A19: TIR anual | B19: =Flujo_Caja!B21 -> 0.78159428
A20: ROI 60 meses | B20: =Flujo_Caja!B24 -> 2.2668912
A21: Payback simple | B21: =Flujo_Caja!B26 -> 22
A22: Payback descontado | B22: =Flujo_Caja!B27 -> 25
A23: EBITDA incremental (año 1 operativo) | B23: =Flujo_Caja!B28 -> 9406419488
A25: ④ RRHH (roster activo)
A26: rol | B26: conteo | C26: fase | D26: costo total mes COP
A27: Equipo diseno y desarrollo ULogix | B27: {=INDEX(RRHH!$B:$B,MATCH(A27,RRHH!$A:$A,0))} -> 7 | C27: {=INDEX(RRHH!$C:$C,MATCH(A27,RRHH!$A:$A,0))} -> Implementacion | D27: {=INDEX(RRHH!$H:$H,MATCH(A27,RRHH!$A:$A,0))} -> 87161760
A28: Operarios de linea (3 turnos) | B28: {=INDEX(RRHH!$B:$B,MATCH(A28,RRHH!$A:$A,0))} -> 18 | C28: {=INDEX(RRHH!$C:$C,MATCH(A28,RRHH!$A:$A,0))} -> Operacion | D28: {=INDEX(RRHH!$H:$H,MATCH(A28,RRHH!$A:$A,0))} -> 68865804
A29: Supervisor de planta | B29: {=INDEX(RRHH!$B:$B,MATCH(A29,RRHH!$A:$A,0))} -> 1 | C29: {=INDEX(RRHH!$C:$C,MATCH(A29,RRHH!$A:$A,0))} -> Operacion | D29: {=INDEX(RRHH!$H:$H,MATCH(A29,RRHH!$A:$A,0))} -> 6732768
A30: Supervisores de turno | B30: {=INDEX(RRHH!$B:$B,MATCH(A30,RRHH!$A:$A,0))} -> 2 | C30: {=INDEX(RRHH!$C:$C,MATCH(A30,RRHH!$A:$A,0))} -> Operacion | D30: {=INDEX(RRHH!$H:$H,MATCH(A30,RRHH!$A:$A,0))} -> 10316810
A31: TOTAL nómina/mes | D31: =SUM(D27:D30) -> 173077142
A33: ⑤ NAVEGACIÓN DEL LIBRO
A34: Demanda/DemandaEscenario | B34: pronóstico y escenario activo (ERP → Sheets)
A35: Tiempos | B35: equipos, tiempos, OEE y capacidad antes vs. después del proyecto
A36: CAPEX | B36: inversión por área (Sheets gobierna — el usuario edita aquí)
A37: RRHH | B37: roster + resumen por rol + carga prestacional
A38: Parametros | B38: supuestos financieros vivos (TRM, TMAR, nómina, precios...)
A39: Sensibilidad | B39: análisis tornado — dónde vale la pena invertir en mejor información
A40: APU_Ingenieria | B40: justificación de los costos de ingeniería que cobra ULogix

Sheet Reportes
A1: REPORTES — tablero financiero integral
A2: Todo por referencia (se recalcula solo): indicadores base vs escenario, resumen anual, sensibilidad, rotacion de inventarios y mapa del ERP.
A4: 1 · INDICADORES DEL PROYECTO
A5: indicador | B5: Base (Demanda v4) | C5: Escenario activo | D5: Δ
A6: VPN @ TMAR (COP) | B6: =Flujo_Caja!B19 -> 11032069063 | C6: =FinancieroEscenario!B21 -> 10832941906 | D6: =C6-B6 -> -1.9912716e+08
A7: TIR anual (E.A.) | B7: =Flujo_Caja!B21 -> 0.78159428 | C7: =FinancieroEscenario!B24 -> 0.76976275 | D7: =C7-B7 -> -0.011831524
A8: ROI 60 meses | B8: =Flujo_Caja!B24 -> 2.2668912 | C8: =FinancieroEscenario!B25 -> 2.2357461 | D8: =C8-B8 -> -0.031145144
A9: ROI anualizado | B9: =Flujo_Caja!B25 -> 0.26714681 | C9: =FinancieroEscenario!B29 -> 0.26472146 | D9: =C9-B9 -> -0.0024253538
A10: Payback simple (mes) | B10: =Flujo_Caja!B26 -> 22 | C10: =FinancieroEscenario!B26 -> 22 | D10: =C10-B10 -> 0
A11: Payback descontado (mes) | B11: =Flujo_Caja!B27 -> 25 | C11: =FinancieroEscenario!B27 -> 26 | D11: =C11-B11 -> 1
A12: EBITDA incremental 12m operativos | B12: =Flujo_Caja!B28 -> 9406419488 | C12: =FinancieroEscenario!B28 -> 9349060283 | D12: =C12-B12 -> -57359205
A13: Inversion pre-operativa (COP) | B13: =Flujo_Caja!B22 -> 9514201285
A14: CAPEX total (COP) | B14: {=INDEX(CAPEX!$G:$G,MATCH("CAPEX TOTAL (con contingencia)",CAPEX!$C:$C,0))} -> 9165554245
A15: Capital de trabajo (COP) | B15: =Flujo_Caja!B29 -> 1.2499736e+08
A17: 2 · RESUMEN ANUAL (incremental)
A18: concepto | B18: Año 1 | C18: Año 2 | D18: Año 3 | E18: Año 4 | F18: Año 5
A19: Ingresos incrementales | B19: =SUM(ER_Proyecto!B17:M17)-SUM(ER_Proyecto!B9:M9) -> 12624025002 | C19: =SUM(ER_Proyecto!N17:Y17)-SUM(ER_Proyecto!N9:Y9) -> 19533494678 | D19: =SUM(ER_Proyecto!Z17:AK17)-SUM(ER_Proyecto!Z9:AK9) -> 19533494678 | E19: =SUM(ER_Proyecto!AL17:AW17)-SUM(ER_Proyecto!AL9:AW9) -> 19533494678 | F19: =SUM(ER_Proyecto!AX17:BI17)-SUM(ER_Proyecto!AX9:BI9) -> 19533494678
A20: EBITDA incremental | B20: =SUM(ER_Proyecto!B25:M25) -> 6237422529 | C20: =SUM(ER_Proyecto!N25:Y25) -> 9678151543 | D20: =SUM(ER_Proyecto!Z25:AK25) -> 9678151543 | E20: =SUM(ER_Proyecto!AL25:AW25) -> 9678151543 | F20: =SUM(ER_Proyecto!AX25:BI25) -> 9678151543
A21: Utilidad neta incremental | B21: =SUM(ER_Proyecto!B29:M29) -> 3559703270 | C21: =SUM(ER_Proyecto!N29:Y29) -> 5548866443 | D21: =SUM(ER_Proyecto!Z29:AK29) -> 5548866443 | E21: =SUM(ER_Proyecto!AL29:AW29) -> 5548866443 | F21: =SUM(ER_Proyecto!AX29:BI29) -> 5548866443
A22: FCF del proyecto | B22: =SUM(Flujo_Caja!B11:M11) -> -5318539419 | C22: =SUM(Flujo_Caja!N11:Y11) -> 6690300382 | D22: =SUM(Flujo_Caja!Z11:AK11) -> 6690300382 | E22: =SUM(Flujo_Caja!AL11:AW11) -> 6690300382 | F22: =SUM(Flujo_Caja!AX11:BI11) -> 6815297745
A23: FCF acumulado (cierre de año) | B23: =Flujo_Caja!M14 -> -5318539419 | C23: =Flujo_Caja!Y14 -> 1371760962 | D23: =Flujo_Caja!AK14 -> 8062061344 | E23: =Flujo_Caja!AW14 -> 14752361726 | F23: =Flujo_Caja!BI14 -> 21567659470
A25: 3 · SENSIBILIDAD RESUMIDA
A26: escenario | B26: VPN (COP) | C26: TIR anual
A27: Conservador | B27: =Sensibilidad!$E$5 -> 8014994753 | C27: =Sensibilidad!$F$5 -> 0.59806155
A28: Base | B28: =Sensibilidad!$E$6 -> 11032069063 | C28: =Sensibilidad!$F$6 -> 0.78159428
A29: Optimista | B29: =Sensibilidad!$E$7 -> 13751069360 | C29: =Sensibilidad!$F$7 -> 0.95882509
A31: 4 · INVENTARIOS
A32: Rotacion del portafolio (veces/año) | B32: =Inventarios!$E$15 -> 21.470588
A33: Dias de inventario | B33: =Inventarios!$F$15 -> 17
A35: 5 · MAPA DEL ERP (quien alimenta cada hoja)
A36: Ventas | B36: Demanda · DemandaEscenario | D36: APP (pronostico v4 / escenario activo)
A37: Produccion | B37: KPIs_UNS · LibroProduccion | D37: Middleware via MQTT-UNS (el ERP NO gestiona OEE)
A38: Produccion (doc.) | B38: Tiempos · OEE_TEEP | D38: Documental para disenos (no conectado)
A39: Compras | B39: PlanCompras | D39: APP (MRP del escenario activo)
A40: Inventario | B40: Inventarios | D40: APP (politica s,Q) + formulas de rotacion
A41: RRHH | B41: Personal | D41: Equipo (editable)
A42: Finanzas | B42: Parametros→CAPEX→Licencias→Costos_Lote→Dep_Amort→ER→Flujo_Caja→Balance→Sensibilidad→Reportes | D42: Formulas vivas

Sheet Parametros
A1: Parametros del modelo — la app los LEE por API
A2: Editar SOLO la columna valor (azul). Amarillo = palancas clave. Fuente: Supuestos/Costos_Lote/Personal/Licencias de la base financiera + BOM reales.
A4: parametro | B4: valor | C4: unidad | D4: fuente / nota
A5: trm_cop_usd | B5: 3248.87 | C5: COP/USD | D5: Superfinanciera; vigencia 11-14 jul-2026
A6: factor_rfq_benchmark | B6: 0.97 | D6: Negociacion RFQ (solo benchmark; celdas ya cotizadas)
A7: tmar_anual | B7: 0.18 | C7: E.A. | D7: BanRep + primas de riesgo
A8: tasa_renta | B8: 0.35 | D8: Art. 240 ET
A9: inflacion_anual | B9: 0.0529 | C9: E.A. | D9: DANE IPC feb-2026
A10: crecimiento_demanda | B10: 0 | C10: anual | D10: YA NO SE APLICA -- pedido explicito del dueno del proyecto: la evaluacion financiera sigue SIEMPRE la demanda que manda el ERP (pronostico/escenario activo), sin inflarla con una tasa de crecimiento interanual aparte. Fila conservada para registro (antes 1,50% aplicado a meses 13-60 via (1+B10)^N en ER_Proyecto/FinancieroEscenario).
A11: uplift_throughput | B11: 0.11 | D11: Objetivo del modelo de negocio (+11%)
A12: factor_monetizacion | B12: 0.31 | D12: Parte del uplift que se vende (demanda > capacidad: hoja Tiempos)
A13: rampa_mes5 | B13: 0.67 | D13: Arranque parcial del primer mes operativo
A14: scrap_pp | B14: 0.0004 | D14: Reduccion de rechazo por inspeccion (0.04 pp)
A15: mant_evitado_mes | B15: 85000000 | C15: COP/mes | D15: Correctivo evitado (base financiera)
A16: wc_pct_ingreso | B16: 0.08 | D16: Capital de trabajo sobre ingreso incremental mensual
A17: dso_dias | B17: 25 | C17: dias | D17: Cuentas por cobrar (Balance)
A18: dio_dias | B18: 17 | C18: dias | D18: Inventarios (Balance y rotacion)
A19: dpo_dias | B19: 30 | C19: dias | D19: Cuentas por pagar (Balance)
A20: precio_p1_350ml | B20: 1800 | C20: COP/u | D20: Costos_Lote (precio ex-factory)
A21: precio_p2_pet15 | B21: 4250 | C21: COP/u | D21: Costos_Lote
A22: precio_p3_garrafon | B22: 12000 | C22: COP/u | D22: Costos_Lote
A23: nomina_operacion_mes | B23: {=INDEX(RRHH!$E:$E,MATCH("Costo mensual OPERACION (→ ER)",RRHH!$A:$A,0))} -> 85915382 | C23: COP/mes | D23: RRHH (resumen por rol, en vivo -- ya no 'Personal', consolidada)
A24: nomina_implementacion_mes | B24: {=INDEX(RRHH!$E:$E,MATCH("Costo mensual IMPLEMENTACION (→ pre-op)",RRHH!$A:$A,0))} -> 87161760 | C24: COP/mes | D24: RRHH (resumen por rol, en vivo -- ya no 'Personal', consolidada)
A25: otros_fijos_base_mes | B25: 250000000 | C25: COP/mes | D25: Base financiera
A26: otros_fijos_proyecto_mes | B26: 280000000 | C26: COP/mes | D26: Base financiera (+30M soporte digital)
A27: contingencia_capex | B27: 0.1 | D27: Sobre subtotal CAPEX
A28: fase_capex_1 | B28: 0.2 | D28: Desembolso mes 1 (ingenieria)
A29: fase_capex_2 | B29: 0.35 | D29: Mes 2 (compra equipos)
A30: fase_capex_3 | B30: 0.27 | D30: Mes 3 (instalacion)
A31: fase_capex_4 | B31: 0.18 | D31: Mes 4 (commissioning)
A32: mejora_oee_relativa | B32: 0.05 | D32: Fase 1: OEE por linea x 1.05 (hoja Tiempos, bloque 'MEJORA DE OEE A IMPLEMENTAR') -- documental, ver core/tiempos_oee.py (data/parametros_planta.json es la fuente real que usa el ERP, decision #1 de CLAUDE.md: OEE/TEEP no se gobierna desde Sheets).
A33: oee_objetivo | B33: 0.82 | D33: Meta de programa
A34: meses_preoperativos | B34: 4 | C34: meses | D34: Cronograma
A35: meses_modelo | B35: 60 | C35: meses | D35: Horizonte
A36: gbp_cop | B36: 4437 | C36: COP/GBP | D36: Referencia de mercado jul-2026 para cotizacion EUROBOTS
A37: fte_manual_equivalente | B37: 10 | C37: FTE | D37: L1: 6 (encajonado+paletizado, 2 turnos); L2: 2; L3: 2
A38: pct_monetizacion_ahorro_laboral | B38: 0.7 | C38: % | D38: Conservador: reconoce reasignacion; editable
A39: ahorro_laboral_monetizable_mes | B39: {=INDEX(Viabilidad_Automatizacion!$B:$B,MATCH("Ahorro laboral bruto mensual",Viabilidad_Automatizacion!$A:$A,0))*B38} -> 26781146 | C39: COP/mes | D39: Formula viva: costo FTE RRHH x FTE equivalentes x monetizacion
A40: eur_cop | B40: 3815.5 | C40: COP/EUR | D40: Referencia 08-jul-2026 para Coreflux; supuesto editable

Sheet Modelo_Negocio
A1: Modelo de negocio — retrofit brownfield FEMSA Fontibon (v3)
A4: elemento | B4: descripcion | C4: hojas relacionadas
A5: Tesis | B5: Conservar las 3 lineas existentes e invertir SOLO donde el estudio de tiempos corregido y el OEE bottom-up demuestran perdidas: paletizado, llenadoras e inspeccion, con gemelo digital por equipo y trazabilidad MES/Cloud via UNS. | C5: Tiempos · OEE_TEEP
A6: Objetivo +11% throughput | B6: Uplift tecnico por OEE (77→81% fase 1) y eliminacion del cuello de paletizado; se monetiza el 31% (parametrizable) porque la demanda SUPERA la capacidad actual. | C6: ER_Proyecto
A7: Hallazgo de capacidad | B7: Con 2 turnos U_2026 = 1.25 (L1) y 1.30 (L2): INFACTIBLE. El 3er turno (nomina ya modelada en Personal) devuelve U a 0.83/0.86. En L3, la celda robotica evita el 2do operario (U=1.61 con uno solo). | C7: Tiempos · Personal
A8: OEE | B8: Fase 1 comprometida: +5% relativo por linea, justificado (+2.0pp disponibilidad celdas/MTTR · +1.2pp rendimiento retrofit llenadoras · +0.7pp calidad inspeccion). Meta de programa ≥86% con mejora continua. KPIs vivos por UNS. | C8: OEE_TEEP · KPIs_UNS
A9: +5% flujo de caja | B9: Verificable en Flujo_Caja/Reportes: EBITDA incremental sobre el caso base supera el objetivo con la demanda v4. | C9: Flujo_Caja · Reportes
A10: Inversion | B10: CAPEX benchmark de retrofit + BOM REAL de celdas (gantry L1-L2 USD 107,993 · robot L3 USD 131,896) + software; contingencia 10%. ⚠ GRP001 pendiente de consolidar. | C10: CAPEX · Licencias
A11: Gobernanza de datos | B11: ERP Ulogix ↔ UNS FEMSA (MQTT) ↔ Odoo ↔ este libro (API Sheets): la demanda elegida en el ERP evalua escenarios financieros en vivo. | C11: Demanda(Escenario) · FinancieroEscenario

Sheet Demanda
A1: Demanda — la escribe la APP (rango fijo A4:F16, NO mover)
A2: VENTAS · Pronostico v4 Base (Abr-26→Mar-27). ER_Proyecto/Flujo_Caja/Balance leen D5:F16. La app la reescribe con publicar_demanda().
A4: escenario | B4: mes_num | C4: etiqueta | D4: P1-CC350-RGB_unidades | E4: P2-QT1500-PET_unidades | F4: P3-GARR25L_unidades
A5: Base | B5: 1 | C5: 46138 | D5: 14359006 | E5: 4241454 | F5: 21691
A6: Base | B6: 2 | C6: 46168 | D6: 14803557 | E6: 4372768 | F6: 22362
A7: Base | B7: 3 | C7: 46199 | D7: 15705552 | E7: 4414001 | F7: 23034
A8: Base | B8: 4 | C8: 46229 | D8: 16744208 | E8: 4651364 | F8: 25180
A9: Base | B9: 5 | C9: 46260 | D9: 15329328 | E9: 4475219 | F9: 23737
A10: Base | B10: 6 | C10: Sep-26 | D10: 14854626 | E10: 4424244 | F10: 23232
A11: Base | B11: 7 | C11: 46321 | D11: 15537720 | E11: 4355974 | F11: 21894
A12: Base | B12: 8 | C12: 46352 | D12: 16178840 | E12: 4673157 | F12: 23028
A13: Base | B13: 9 | C13: 46382 | D13: 18771980 | E13: 5469074 | F13: 25933
A14: Base | B14: 10 | C14: 46049 | D14: 15568902 | E14: 4430554 | F14: 23273
A15: Base | B15: 11 | C15: 46080 | D15: 14407009 | E15: 4099488 | F15: 21753
A16: Base | B16: 12 | C16: 46108 | D16: 16077086 | E16: 4621386 | F16: 24032

Sheet DemandaEscenario
A1: DemandaEscenario — la escribe la APP (rango fijo A4:F16, NO mover)
A2: VENTAS · Demanda del ESCENARIO ACTIVO elegido en el ERP (pagina Escenarios → Activar). FinancieroEscenario la evalua. publicar_demanda_escenario().
A4: escenario | B4: mes_num | C4: etiqueta | D4: P1-CC350-RGB_unidades | E4: P2-QT1500-PET_unidades | F4: P3-GARR25L_unidades
A5: Paro nacional / choque logistico | B5: 1 | C5: 46138 | D5: 14359007 | E5: 4241455 | F5: 21681
A6: Paro nacional / choque logistico | B6: 2 | C6: 46168 | D6: 14803558 | E6: 4372769 | F6: 22352
A7: Paro nacional / choque logistico | B7: 3 | C7: 46199 | D7: 15705553 | E7: 4414002 | F7: 23023
A8: Paro nacional / choque logistico | B8: 4 | C8: 46229 | D8: 16744208 | E8: 4651367 | F8: 25177
A9: Paro nacional / choque logistico | B9: 5 | C9: 46260 | D9: 12570049 | E9: 3669682 | F9: 19462
A10: Paro nacional / choque logistico | B10: 6 | C10: Sep-26 | D10: 14854626 | E10: 4424247 | F10: 23229
A11: Paro nacional / choque logistico | B11: 7 | C11: 46321 | D11: 16159229 | E11: 4530217 | F11: 22767
A12: Paro nacional / choque logistico | B12: 8 | C12: 46352 | D12: 16178840 | E12: 4673161 | F12: 23024
A13: Paro nacional / choque logistico | B13: 9 | C13: 46382 | D13: 18771980 | E13: 5469078 | F13: 25929
A14: Paro nacional / choque logistico | B14: 10 | C14: 46049 | D14: 15568902 | E14: 4430558 | F14: 23267
A15: Paro nacional / choque logistico | B15: 11 | C15: 46080 | D15: 14407009 | E15: 4099491 | F15: 21748
A16: Paro nacional / choque logistico | B16: 12 | C16: 46108 | D16: 16077085 | E16: 4621389 | F16: 24027

Sheet ER_Proyecto
A1: Estado de resultados mensual — caso BASE vs PROYECTO (demanda v4)
A2: Proyecto incluye ahorro laboral monetizable vinculado a Viabilidad_Automatizacion/Parametros; porcentaje editable y conservador.
A4: Mes | B4: 1 | C4: 2 | D4: 3 | E4: 4 | F4: 5 | G4: 6 | H4: 7 | I4: 8 | J4: 9 | K4: 10 | L4: 11 | M4: 12 | N4: 13 | O4: 14 | P4: 15 | Q4: 16 | R4: 17 | S4: 18 | T4: 19 | U4: 20 | V4: 21 | W4: 22 | X4: 23 | Y4: 24 | Z4: 25 | AA4: 26 | AB4: 27 | AC4: 28 | AD4: 29 | AE4: 30 | AF4: 31 | AG4: 32 | AH4: 33 | AI4: 34 | AJ4: 35 | AK4: 36 | AL4: 37 | AM4: 38 | AN4: 39 | AO4: 40 | AP4: 41 | AQ4: 42 | AR4: 43 | AS4: 44 | AT4: 45 | AU4: 46 | AV4: 47 | AW4: 48 | AX4: 49 | AY4: 50 | AZ4: 51 | BA4: 52 | BB4: 53 | BC4: 54 | BD4: 55 | BE4: 56 | BF4: 57 | BG4: 58 | BH4: 59 | BI4: 60
A5: CASO BASE (sin proyecto)
A6: Ventas u P1 (330/350 mL) | B6: =Demanda!$D$5 -> 14359006 | C6: =Demanda!$D$6 -> 14803557 | D6: =Demanda!$D$7 -> 15705552 | E6: =Demanda!$D$8 -> 16744208 | F6: =Demanda!$D$9 -> 15329328 | G6: =Demanda!$D$10 -> 14854626 | H6: =Demanda!$D$11 -> 15537720 | I6: =Demanda!$D$12 -> 16178840 | J6: =Demanda!$D$13 -> 18771980 | K6: =Demanda!$D$14 -> 15568902 | L6: =Demanda!$D$15 -> 14407009 | M6: =Demanda!$D$16 -> 16077086 | N6: =Demanda!$D$5*(1+Parametros!$B$10)^1 -> 14359006 | O6: =Demanda!$D$6*(1+Parametros!$B$10)^1 -> 14803557 | P6: =Demanda!$D$7*(1+Parametros!$B$10)^1 -> 15705552 | Q6: =Demanda!$D$8*(1+Parametros!$B$10)^1 -> 16744208 | R6: =Demanda!$D$9*(1+Parametros!$B$10)^1 -> 15329328 | S6: =Demanda!$D$10*(1+Parametros!$B$10)^1 -> 14854626 | T6: =Demanda!$D$11*(1+Parametros!$B$10)^1 -> 15537720 | U6: =Demanda!$D$12*(1+Parametros!$B$10)^1 -> 16178840 | V6: =Demanda!$D$13*(1+Parametros!$B$10)^1 -> 18771980 | W6: =Demanda!$D$14*(1+Parametros!$B$10)^1 -> 15568902 | X6: =Demanda!$D$15*(1+Parametros!$B$10)^1 -> 14407009 | Y6: =Demanda!$D$16*(1+Parametros!$B$10)^1 -> 16077086 | Z6: =Demanda!$D$5*(1+Parametros!$B$10)^2 -> 14359006 | AA6: =Demanda!$D$6*(1+Parametros!$B$10)^2 -> 14803557 | AB6: =Demanda!$D$7*(1+Parametros!$B$10)^2 -> 15705552 | AC6: =Demanda!$D$8*(1+Parametros!$B$10)^2 -> 16744208 | AD6: =Demanda!$D$9*(1+Parametros!$B$10)^2 -> 15329328 | AE6: =Demanda!$D$10*(1+Parametros!$B$10)^2 -> 14854626 | AF6: =Demanda!$D$11*(1+Parametros!$B$10)^2 -> 15537720 | AG6: =Demanda!$D$12*(1+Parametros!$B$10)^2 -> 16178840 | AH6: =Demanda!$D$13*(1+Parametros!$B$10)^2 -> 18771980 | AI6: =Demanda!$D$14*(1+Parametros!$B$10)^2 -> 15568902 | AJ6: =Demanda!$D$15*(1+Parametros!$B$10)^2 -> 14407009 | AK6: =Demanda!$D$16*(1+Parametros!$B$10)^2 -> 16077086 | AL6: =Demanda!$D$5*(1+Parametros!$B$10)^3 -> 14359006 | AM6: =Demanda!$D$6*(1+Parametros!$B$10)^3 -> 14803557 | AN6: =Demanda!$D$7*(1+Parametros!$B$10)^3 -> 15705552 | AO6: =Demanda!$D$8*(1+Parametros!$B$10)^3 -> 16744208 | AP6: =Demanda!$D$9*(1+Parametros!$B$10)^3 -> 15329328 | AQ6: =Demanda!$D$10*(1+Parametros!$B$10)^3 -> 14854626 | AR6: =Demanda!$D$11*(1+Parametros!$B$10)^3 -> 15537720 | AS6: =Demanda!$D$12*(1+Parametros!$B$10)^3 -> 16178840 | AT6: =Demanda!$D$13*(1+Parametros!$B$10)^3 -> 18771980 | AU6: =Demanda!$D$14*(1+Parametros!$B$10)^3 -> 15568902 | AV6: =Demanda!$D$15*(1+Parametros!$B$10)^3 -> 14407009 | AW6: =Demanda!$D$16*(1+Parametros!$B$10)^3 -> 16077086 | AX6: =Demanda!$D$5*(1+Parametros!$B$10)^4 -> 14359006 | AY6: =Demanda!$D$6*(1+Parametros!$B$10)^4 -> 14803557 | AZ6: =Demanda!$D$7*(1+Parametros!$B$10)^4 -> 15705552 | BA6: =Demanda!$D$8*(1+Parametros!$B$10)^4 -> 16744208 | BB6: =Demanda!$D$9*(1+Parametros!$B$10)^4 -> 15329328 | BC6: =Demanda!$D$10*(1+Parametros!$B$10)^4 -> 14854626 | BD6: =Demanda!$D$11*(1+Parametros!$B$10)^4 -> 15537720 | BE6: =Demanda!$D$12*(1+Parametros!$B$10)^4 -> 16178840 | BF6: =Demanda!$D$13*(1+Parametros!$B$10)^4 -> 18771980 | BG6: =Demanda!$D$14*(1+Parametros!$B$10)^4 -> 15568902 | BH6: =Demanda!$D$15*(1+Parametros!$B$10)^4 -> 14407009 | BI6: =Demanda!$D$16*(1+Parametros!$B$10)^4 -> 16077086
A7: Ventas u P2 (PET 1.5 L) | B7: =Demanda!$E$5 -> 4241454 | C7: =Demanda!$E$6 -> 4372768 | D7: =Demanda!$E$7 -> 4414001 | E7: =Demanda!$E$8 -> 4651364 | F7: =Demanda!$E$9 -> 4475219 | G7: =Demanda!$E$10 -> 4424244 | H7: =Demanda!$E$11 -> 4355974 | I7: =Demanda!$E$12 -> 4673157 | J7: =Demanda!$E$13 -> 5469074 | K7: =Demanda!$E$14 -> 4430554 | L7: =Demanda!$E$15 -> 4099488 | M7: =Demanda!$E$16 -> 4621386 | N7: =Demanda!$E$5*(1+Parametros!$B$10)^1 -> 4241454 | O7: =Demanda!$E$6*(1+Parametros!$B$10)^1 -> 4372768 | P7: =Demanda!$E$7*(1+Parametros!$B$10)^1 -> 4414001 | Q7: =Demanda!$E$8*(1+Parametros!$B$10)^1 -> 4651364 | R7: =Demanda!$E$9*(1+Parametros!$B$10)^1 -> 4475219 | S7: =Demanda!$E$10*(1+Parametros!$B$10)^1 -> 4424244 | T7: =Demanda!$E$11*(1+Parametros!$B$10)^1 -> 4355974 | U7: =Demanda!$E$12*(1+Parametros!$B$10)^1 -> 4673157 | V7: =Demanda!$E$13*(1+Parametros!$B$10)^1 -> 5469074 | W7: =Demanda!$E$14*(1+Parametros!$B$10)^1 -> 4430554 | X7: =Demanda!$E$15*(1+Parametros!$B$10)^1 -> 4099488 | Y7: =Demanda!$E$16*(1+Parametros!$B$10)^1 -> 4621386 | Z7: =Demanda!$E$5*(1+Parametros!$B$10)^2 -> 4241454 | AA7: =Demanda!$E$6*(1+Parametros!$B$10)^2 -> 4372768 | AB7: =Demanda!$E$7*(1+Parametros!$B$10)^2 -> 4414001 | AC7: =Demanda!$E$8*(1+Parametros!$B$10)^2 -> 4651364 | AD7: =Demanda!$E$9*(1+Parametros!$B$10)^2 -> 4475219 | AE7: =Demanda!$E$10*(1+Parametros!$B$10)^2 -> 4424244 | AF7: =Demanda!$E$11*(1+Parametros!$B$10)^2 -> 4355974 | AG7: =Demanda!$E$12*(1+Parametros!$B$10)^2 -> 4673157 | AH7: =Demanda!$E$13*(1+Parametros!$B$10)^2 -> 5469074 | AI7: =Demanda!$E$14*(1+Parametros!$B$10)^2 -> 4430554 | AJ7: =Demanda!$E$15*(1+Parametros!$B$10)^2 -> 4099488 | AK7: =Demanda!$E$16*(1+Parametros!$B$10)^2 -> 4621386 | AL7: =Demanda!$E$5*(1+Parametros!$B$10)^3 -> 4241454 | AM7: =Demanda!$E$6*(1+Parametros!$B$10)^3 -> 4372768 | AN7: =Demanda!$E$7*(1+Parametros!$B$10)^3 -> 4414001 | AO7: =Demanda!$E$8*(1+Parametros!$B$10)^3 -> 4651364 | AP7: =Demanda!$E$9*(1+Parametros!$B$10)^3 -> 4475219 | AQ7: =Demanda!$E$10*(1+Parametros!$B$10)^3 -> 4424244 | AR7: =Demanda!$E$11*(1+Parametros!$B$10)^3 -> 4355974 | AS7: =Demanda!$E$12*(1+Parametros!$B$10)^3 -> 4673157 | AT7: =Demanda!$E$13*(1+Parametros!$B$10)^3 -> 5469074 | AU7: =Demanda!$E$14*(1+Parametros!$B$10)^3 -> 4430554 | AV7: =Demanda!$E$15*(1+Parametros!$B$10)^3 -> 4099488 | AW7: =Demanda!$E$16*(1+Parametros!$B$10)^3 -> 4621386 | AX7: =Demanda!$E$5*(1+Parametros!$B$10)^4 -> 4241454 | AY7: =Demanda!$E$6*(1+Parametros!$B$10)^4 -> 4372768 | AZ7: =Demanda!$E$7*(1+Parametros!$B$10)^4 -> 4414001 | BA7: =Demanda!$E$8*(1+Parametros!$B$10)^4 -> 4651364 | BB7: =Demanda!$E$9*(1+Parametros!$B$10)^4 -> 4475219 | BC7: =Demanda!$E$10*(1+Parametros!$B$10)^4 -> 4424244 | BD7: =Demanda!$E$11*(1+Parametros!$B$10)^4 -> 4355974 | BE7: =Demanda!$E$12*(1+Parametros!$B$10)^4 -> 4673157 | BF7: =Demanda!$E$13*(1+Parametros!$B$10)^4 -> 5469074 | BG7: =Demanda!$E$14*(1+Parametros!$B$10)^4 -> 4430554 | BH7: =Demanda!$E$15*(1+Parametros!$B$10)^4 -> 4099488 | BI7: =Demanda!$E$16*(1+Parametros!$B$10)^4 -> 4621386
A8: Ventas u P3 (garrafon) | B8: =Demanda!$F$5 -> 21691 | C8: =Demanda!$F$6 -> 22362 | D8: =Demanda!$F$7 -> 23034 | E8: =Demanda!$F$8 -> 25180 | F8: =Demanda!$F$9 -> 23737 | G8: =Demanda!$F$10 -> 23232 | H8: =Demanda!$F$11 -> 21894 | I8: =Demanda!$F$12 -> 23028 | J8: =Demanda!$F$13 -> 25933 | K8: =Demanda!$F$14 -> 23273 | L8: =Demanda!$F$15 -> 21753 | M8: =Demanda!$F$16 -> 24032 | N8: =Demanda!$F$5*(1+Parametros!$B$10)^1 -> 21691 | O8: =Demanda!$F$6*(1+Parametros!$B$10)^1 -> 22362 | P8: =Demanda!$F$7*(1+Parametros!$B$10)^1 -> 23034 | Q8: =Demanda!$F$8*(1+Parametros!$B$10)^1 -> 25180 | R8: =Demanda!$F$9*(1+Parametros!$B$10)^1 -> 23737 | S8: =Demanda!$F$10*(1+Parametros!$B$10)^1 -> 23232 | T8: =Demanda!$F$11*(1+Parametros!$B$10)^1 -> 21894 | U8: =Demanda!$F$12*(1+Parametros!$B$10)^1 -> 23028 | V8: =Demanda!$F$13*(1+Parametros!$B$10)^1 -> 25933 | W8: =Demanda!$F$14*(1+Parametros!$B$10)^1 -> 23273 | X8: =Demanda!$F$15*(1+Parametros!$B$10)^1 -> 21753 | Y8: =Demanda!$F$16*(1+Parametros!$B$10)^1 -> 24032 | Z8: =Demanda!$F$5*(1+Parametros!$B$10)^2 -> 21691 | AA8: =Demanda!$F$6*(1+Parametros!$B$10)^2 -> 22362 | AB8: =Demanda!$F$7*(1+Parametros!$B$10)^2 -> 23034 | AC8: =Demanda!$F$8*(1+Parametros!$B$10)^2 -> 25180 | AD8: =Demanda!$F$9*(1+Parametros!$B$10)^2 -> 23737 | AE8: =Demanda!$F$10*(1+Parametros!$B$10)^2 -> 23232 | AF8: =Demanda!$F$11*(1+Parametros!$B$10)^2 -> 21894 | AG8: =Demanda!$F$12*(1+Parametros!$B$10)^2 -> 23028 | AH8: =Demanda!$F$13*(1+Parametros!$B$10)^2 -> 25933 | AI8: =Demanda!$F$14*(1+Parametros!$B$10)^2 -> 23273 | AJ8: =Demanda!$F$15*(1+Parametros!$B$10)^2 -> 21753 | AK8: =Demanda!$F$16*(1+Parametros!$B$10)^2 -> 24032 | AL8: =Demanda!$F$5*(1+Parametros!$B$10)^3 -> 21691 | AM8: =Demanda!$F$6*(1+Parametros!$B$10)^3 -> 22362 | AN8: =Demanda!$F$7*(1+Parametros!$B$10)^3 -> 23034 | AO8: =Demanda!$F$8*(1+Parametros!$B$10)^3 -> 25180 | AP8: =Demanda!$F$9*(1+Parametros!$B$10)^3 -> 23737 | AQ8: =Demanda!$F$10*(1+Parametros!$B$10)^3 -> 23232 | AR8: =Demanda!$F$11*(1+Parametros!$B$10)^3 -> 21894 | AS8: =Demanda!$F$12*(1+Parametros!$B$10)^3 -> 23028 | AT8: =Demanda!$F$13*(1+Parametros!$B$10)^3 -> 25933 | AU8: =Demanda!$F$14*(1+Parametros!$B$10)^3 -> 23273 | AV8: =Demanda!$F$15*(1+Parametros!$B$10)^3 -> 21753 | AW8: =Demanda!$F$16*(1+Parametros!$B$10)^3 -> 24032 | AX8: =Demanda!$F$5*(1+Parametros!$B$10)^4 -> 21691 | AY8: =Demanda!$F$6*(1+Parametros!$B$10)^4 -> 22362 | AZ8: =Demanda!$F$7*(1+Parametros!$B$10)^4 -> 23034 | BA8: =Demanda!$F$8*(1+Parametros!$B$10)^4 -> 25180 | BB8: =Demanda!$F$9*(1+Parametros!$B$10)^4 -> 23737 | BC8: =Demanda!$F$10*(1+Parametros!$B$10)^4 -> 23232 | BD8: =Demanda!$F$11*(1+Parametros!$B$10)^4 -> 21894 | BE8: =Demanda!$F$12*(1+Parametros!$B$10)^4 -> 23028 | BF8: =Demanda!$F$13*(1+Parametros!$B$10)^4 -> 25933 | BG8: =Demanda!$F$14*(1+Parametros!$B$10)^4 -> 23273 | BH8: =Demanda!$F$15*(1+Parametros!$B$10)^4 -> 21753 | BI8: =Demanda!$F$16*(1+Parametros!$B$10)^4 -> 24032
A9: Ingresos base | B9: =B6*Parametros!$B$20+B7*Parametros!$B$21+B8*Parametros!$B$22 -> 44132682300 | C9: =C6*Parametros!$B$20+C7*Parametros!$B$21+C8*Parametros!$B$22 -> 45499010600 | D9: =D6*Parametros!$B$20+D7*Parametros!$B$21+D8*Parametros!$B$22 -> 47305905850 | E9: =E6*Parametros!$B$20+E7*Parametros!$B$21+E8*Parametros!$B$22 -> 50210031400 | F9: =F6*Parametros!$B$20+F7*Parametros!$B$21+F8*Parametros!$B$22 -> 46897315150 | G9: =G6*Parametros!$B$20+G7*Parametros!$B$21+G8*Parametros!$B$22 -> 45820147800 | H9: =H6*Parametros!$B$20+H7*Parametros!$B$21+H8*Parametros!$B$22 -> 46743513500 | I9: =I6*Parametros!$B$20+I7*Parametros!$B$21+I8*Parametros!$B$22 -> 49259165250 | ... BI9: =BI6*Parametros!$B$20+BI7*Parametros!$B$21+BI8*Parametros!$B$22 -> 48868029300
A10: COGS variable base | B10: =B6*Costos_Lote!$B$18+B7*Costos_Lote!$B$33+B8*Costos_Lote!$B$46 -> 24814796268 | C10: =C6*Costos_Lote!$B$18+C7*Costos_Lote!$B$33+C8*Costos_Lote!$B$46 -> 25583051184 | D10: =D6*Costos_Lote!$B$18+D7*Costos_Lote!$B$33+D8*Costos_Lote!$B$46 -> 26535762249 | E10: =E6*Costos_Lote!$B$18+E7*Costos_Lote!$B$33+E8*Costos_Lote!$B$46 -> 28149332255 | F10: =F6*Costos_Lote!$B$18+F7*Costos_Lote!$B$33+F8*Costos_Lote!$B$46 -> 26354583042 | G10: =G6*Costos_Lote!$B$18+G7*Costos_Lote!$B$33+G8*Costos_Lote!$B$46 -> 25773975491 | H10: =H6*Costos_Lote!$B$18+H7*Costos_Lote!$B$33+H8*Costos_Lote!$B$46 -> 26216999374 | I10: =I6*Costos_Lote!$B$18+I7*Costos_Lote!$B$33+I8*Costos_Lote!$B$46 -> 27667351664 | ... BI10: =BI6*Costos_Lote!$B$18+BI7*Costos_Lote!$B$33+BI8*Costos_Lote!$B$46 -> 27441564257
A11: Utilidad bruta base | B11: =B9-B10 -> 19317886032 | C11: =C9-C10 -> 19915959416 | D11: =D9-D10 -> 20770143601 | E11: =E9-E10 -> 22060699145 | F11: =F9-F10 -> 20542732108 | G11: =G9-G10 -> 20046172309 | H11: =H9-H10 -> 20526514126 | I11: =I9-I10 -> 21591813586 | ... BI11: =BI9-BI10 -> 21426465043
A12: Nomina operacion | B12: {=INDEX(RRHH!$E:$E,MATCH("Costo mensual OPERACION (→ ER)",RRHH!$A:$A,0))} -> 85915382 | C12: {=INDEX(RRHH!$E:$E,MATCH("Costo mensual OPERACION (→ ER)",RRHH!$A:$A,0))} -> 85915382 | D12: {=INDEX(RRHH!$E:$E,MATCH("Costo mensual OPERACION (→ ER)",RRHH!$A:$A,0))} -> 85915382 | E12: {=INDEX(RRHH!$E:$E,MATCH("Costo mensual OPERACION (→ ER)",RRHH!$A:$A,0))} -> 85915382 | F12: {=INDEX(RRHH!$E:$E,MATCH("Costo mensual OPERACION (→ ER)",RRHH!$A:$A,0))} -> 85915382 | G12: {=INDEX(RRHH!$E:$E,MATCH("Costo mensual OPERACION (→ ER)",RRHH!$A:$A,0))} -> 85915382 | H12: {=INDEX(RRHH!$E:$E,MATCH("Costo mensual OPERACION (→ ER)",RRHH!$A:$A,0))} -> 85915382 | I12: {=INDEX(RRHH!$E:$E,MATCH("Costo mensual OPERACION (→ ER)",RRHH!$A:$A,0))} -> 85915382 | ... BI12: {=INDEX(RRHH!$E:$E,MATCH("Costo mensual OPERACION (→ ER)",RRHH!$A:$A,0))} -> 85915382
A13: Otros fijos base | B13: =Parametros!$B$25 -> 250000000 | C13: =Parametros!$B$25 -> 250000000 | D13: =Parametros!$B$25 -> 250000000 | E13: =Parametros!$B$25 -> 250000000 | F13: =Parametros!$B$25 -> 250000000 | G13: =Parametros!$B$25 -> 250000000 | H13: =Parametros!$B$25 -> 250000000 | I13: =Parametros!$B$25 -> 250000000 | ... BI13: =Parametros!$B$25 -> 250000000
A14: EBITDA base | B14: =B11-B12-B13 -> 18981970650 | C14: =C11-C12-C13 -> 19580044034 | D14: =D11-D12-D13 -> 20434228219 | E14: =E11-E12-E13 -> 21724783763 | F14: =F11-F12-F13 -> 20206816726 | G14: =G11-G12-G13 -> 19710256927 | H14: =H11-H12-H13 -> 20190598744 | I14: =I11-I12-I13 -> 21255898204 | ... BI14: =BI11-BI12-BI13 -> 21090549661
A15: CASO PROYECTO (retrofit)
A16: Factor ventas (uplift monetizado) | B16: =1 -> 1 | C16: =1 -> 1 | D16: =1 -> 1 | E16: =1 -> 1 | F16: =1+Parametros!$B$13*Parametros!$B$11*Parametros!$B$12 -> 1.022847 | G16: =1+Parametros!$B$11*Parametros!$B$12 -> 1.0341 | H16: =1+Parametros!$B$11*Parametros!$B$12 -> 1.0341 | I16: =1+Parametros!$B$11*Parametros!$B$12 -> 1.0341 | J16: =1+Parametros!$B$11*Parametros!$B$12 -> 1.0341 | K16: =1+Parametros!$B$11*Parametros!$B$12 -> 1.0341 | L16: =1+Parametros!$B$11*Parametros!$B$12 -> 1.0341 | M16: =1+Parametros!$B$11*Parametros!$B$12 -> 1.0341 | N16: =1+Parametros!$B$11*Parametros!$B$12 -> 1.0341 | ... BI16: =1+Parametros!$B$11*Parametros!$B$12 -> 1.0341
A17: Ingresos proyecto | B17: =B9*B16 -> 44132682300 | C17: =C9*C16 -> 45499010600 | D17: =D9*D16 -> 47305905850 | E17: =E9*E16 -> 50210031400 | F17: =F9*F16 -> 47968778109 | G17: =G9*G16 -> 47382614840 | H17: =H9*H16 -> 48337467310 | I17: =I9*I16 -> 50938902785 | ... BI17: =BI9*BI16 -> 50534429099
A18: COGS variable proyecto | B18: =B10*B16 -> 24814796268 | C18: =C10*C16 -> 25583051184 | D18: =D10*D16 -> 26535762249 | E18: =E10*E16 -> 28149332255 | F18: =F10*F16 -> 26956706201 | G18: =G10*G16 -> 26652868055 | H18: =H10*H16 -> 27110999053 | I18: =I10*I16 -> 28610808356 | ... BI18: =BI10*BI16 -> 28377321598
A19: (+) Ahorro de scrap | B19: =B18*Parametros!$B$14*0 -> 0 | C19: =C18*Parametros!$B$14*0 -> 0 | D19: =D18*Parametros!$B$14*0 -> 0 | E19: =E18*Parametros!$B$14*0 -> 0 | F19: =F18*Parametros!$B$14*Parametros!$B$13 -> 7224397.3 | G19: =G18*Parametros!$B$14*1 -> 10661147 | H19: =H18*Parametros!$B$14*1 -> 10844400 | I19: =I18*Parametros!$B$14*1 -> 11444323 | J19: =J18*Parametros!$B$14*1 -> 13328162 | K19: =K18*Parametros!$B$14*1 -> 10942710 | L19: =L18*Parametros!$B$14*1 -> 10126227 | M19: =M18*Parametros!$B$14*1 -> 11350929 | N19: =N18*Parametros!$B$14*1 -> 10264392 | ... BI19: =BI18*Parametros!$B$14*1 -> 11350929
A20: (+) Mantenimiento correctivo evitado | B20: =Parametros!$B$15*0 -> 0 | C20: =Parametros!$B$15*0 -> 0 | D20: =Parametros!$B$15*0 -> 0 | E20: =Parametros!$B$15*0 -> 0 | F20: =Parametros!$B$15*Parametros!$B$13 -> 56950000 | G20: =Parametros!$B$15*1 -> 85000000 | H20: =Parametros!$B$15*1 -> 85000000 | I20: =Parametros!$B$15*1 -> 85000000 | J20: =Parametros!$B$15*1 -> 85000000 | K20: =Parametros!$B$15*1 -> 85000000 | L20: =Parametros!$B$15*1 -> 85000000 | M20: =Parametros!$B$15*1 -> 85000000 | N20: =Parametros!$B$15*1 -> 85000000 | ... BI20: =Parametros!$B$15*1 -> 85000000
A21: Otros fijos proyecto | B21: =Parametros!$B$25 -> 250000000 | C21: =Parametros!$B$25 -> 250000000 | D21: =Parametros!$B$25 -> 250000000 | E21: =Parametros!$B$25 -> 250000000 | F21: =Parametros!$B$26 -> 280000000 | G21: =Parametros!$B$26 -> 280000000 | H21: =Parametros!$B$26 -> 280000000 | I21: =Parametros!$B$26 -> 280000000 | J21: =Parametros!$B$26 -> 280000000 | K21: =Parametros!$B$26 -> 280000000 | L21: =Parametros!$B$26 -> 280000000 | M21: =Parametros!$B$26 -> 280000000 | ... BI21: =Parametros!$B$26 -> 280000000
A22: OPEX licencias | B22: =Licencias!$H$14 -> 0 | C22: =Licencias!$H$14 -> 0 | D22: =Licencias!$H$14 -> 0 | E22: =Licencias!$H$14 -> 0 | F22: =Licencias!$H$14 -> 0 | G22: =Licencias!$H$14 -> 0 | H22: =Licencias!$H$14 -> 0 | I22: =Licencias!$H$14 -> 0 | ... BI22: =Licencias!$H$14 -> 0
A23: EBITDA proyecto | B23: {=B17-B18-B12-B21-B22+B19+B20+INDEX(Parametros!$B:$B,MATCH("ahorro_laboral_monetizable_mes",Parametros!$A:$A,0))*IF(1<=4,0,IF(1=5,Parametros!$B$13,1))} -> 18981970650 | C23: {=C17-C18-C12-C21-C22+C19+C20+INDEX(Parametros!$B:$B,MATCH("ahorro_laboral_monetizable_mes",Parametros!$A:$A,0))*IF(2<=4,0,IF(2=5,Parametros!$B$13,1))} -> 19580044034 | D23: {=D17-D18-D12-D21-D22+D19+D20+INDEX(Parametros!$B:$B,MATCH("ahorro_laboral_monetizable_mes",Parametros!$A:$A,0))*IF(3<=4,0,IF(3=5,Parametros!$B$13,1))} -> 20434228219 | E23: {=E17-E18-E12-E21-E22+E19+E20+INDEX(Parametros!$B:$B,MATCH("ahorro_laboral_monetizable_mes",Parametros!$A:$A,0))*IF(4<=4,0,IF(4=5,Parametros!$B$13,1))} -> 21724783763 | F23: {=F17-F18-F12-F21-F22+F19+F20+INDEX(Parametros!$B:$B,MATCH("ahorro_laboral_monetizable_mes",Parametros!$A:$A,0))*IF(5<=4,0,IF(5=5,Parametros!$B$13,1))} -> 20728274292 | G23: {=G17-G18-G12-G21-G22+G19+G20+INDEX(Parametros!$B:$B,MATCH("ahorro_laboral_monetizable_mes",Parametros!$A:$A,0))*IF(6<=4,0,IF(6=5,Parametros!$B$13,1))} -> 20486273696 | H23: {=H17-H18-H12-H21-H22+H19+H20+INDEX(Parametros!$B:$B,MATCH("ahorro_laboral_monetizable_mes",Parametros!$A:$A,0))*IF(7<=4,0,IF(7=5,Parametros!$B$13,1))} -> 20983178421 | I23: {=I17-I18-I12-I21-I22+I19+I20+INDEX(Parametros!$B:$B,MATCH("ahorro_laboral_monetizable_mes",Parametros!$A:$A,0))*IF(8<=4,0,IF(8=5,Parametros!$B$13,1))} -> 22085404516 | J23: {=J17-J18-J12-J21-J22+J19+J20+INDEX(Parametros!$B:$B,MATCH("ahorro_laboral_monetizable_mes",Parametros!$A:$A,0))*IF(9<=4,0,IF(9=5,Parametros!$B$13,1))} -> 25738555644 | K23: {=K17-K18-K12-K21-K22+K19+K20+INDEX(Parametros!$B:$B,MATCH("ahorro_laboral_monetizable_mes",Parametros!$A:$A,0))*IF(10<=4,0,IF(10=5,Parametros!$B$13,1))} -> 21140428621 | L23: {=L17-L18-L12-L21-L22+L19+L20+INDEX(Parametros!$B:$B,MATCH("ahorro_laboral_monetizable_mes",Parametros!$A:$A,0))*IF(11<=4,0,IF(11=5,Parametros!$B$13,1))} -> 19544223401 | M23: {=M17-M18-M12-M21-M22+M19+M20+INDEX(Parametros!$B:$B,MATCH("ahorro_laboral_monetizable_mes",Parametros!$A:$A,0))*IF(12<=4,0,IF(12=5,Parametros!$B$13,1))} -> 21914324194 | N23: {=N17-N18-N12-N21-N22+N19+N20+INDEX(Parametros!$B:$B,MATCH("ahorro_laboral_monetizable_mes",Parametros!$A:$A,0))*IF(13<=4,0,IF(13=5,Parametros!$B$13,1))} -> 19732756102 | O23: {=O17-O18-O12-O21-O22+O19+O20+INDEX(Parametros!$B:$B,MATCH("ahorro_laboral_monetizable_mes",Parametros!$A:$A,0))*IF(14<=4,0,IF(14=5,Parametros!$B$13,1))} -> 20351541569 | P23: {=P17-P18-P12-P21-P22+P19+P20+INDEX(Parametros!$B:$B,MATCH("ahorro_laboral_monetizable_mes",Parametros!$A:$A,0))*IF(15<=4,0,IF(15=5,Parametros!$B$13,1))} -> 21235247514 | Q23: {=Q17-Q18-Q12-Q21-Q22+Q19+Q20+INDEX(Parametros!$B:$B,MATCH("ahorro_laboral_monetizable_mes",Parametros!$A:$A,0))*IF(16<=4,0,IF(16=5,Parametros!$B$13,1))} -> 22570478440 | R23: {=R17-R18-R12-R21-R22+R19+R20+INDEX(Parametros!$B:$B,MATCH("ahorro_laboral_monetizable_mes",Parametros!$A:$A,0))*IF(17<=4,0,IF(17=5,Parametros!$B$13,1))} -> 21000006347 | S23: {=S17-S18-S12-S21-S22+S19+S20+INDEX(Parametros!$B:$B,MATCH("ahorro_laboral_monetizable_mes",Parametros!$A:$A,0))*IF(18<=4,0,IF(18=5,Parametros!$B$13,1))} -> 20486273696 | T23: {=T17-T18-T12-T21-T22+T19+T20+INDEX(Parametros!$B:$B,MATCH("ahorro_laboral_monetizable_mes",Parametros!$A:$A,0))*IF(19<=4,0,IF(19=5,Parametros!$B$13,1))} -> 20983178421 | U23: {=U17-U18-U12-U21-U22+U19+U20+INDEX(Parametros!$B:$B,MATCH("ahorro_laboral_monetizable_mes",Parametros!$A:$A,0))*IF(20<=4,0,IF(20=5,Parametros!$B$13,1))} -> 22085404516 | V23: {=V17-V18-V12-V21-V22+V19+V20+INDEX(Parametros!$B:$B,MATCH("ahorro_laboral_monetizable_mes",Parametros!$A:$A,0))*IF(21<=4,0,IF(21=5,Parametros!$B$13,1))} -> 25738555644 | W23: {=W17-W18-W12-W21-W22+W19+W20+INDEX(Parametros!$B:$B,MATCH("ahorro_laboral_monetizable_mes",Parametros!$A:$A,0))*IF(22<=4,0,IF(22=5,Parametros!$B$13,1))} -> 21140428621 | X23: {=X17-X18-X12-X21-X22+X19+X20+INDEX(Parametros!$B:$B,MATCH("ahorro_laboral_monetizable_mes",Parametros!$A:$A,0))*IF(23<=4,0,IF(23=5,Parametros!$B$13,1))} -> 19544223401 | Y23: {=Y17-Y18-Y12-Y21-Y22+Y19+Y20+INDEX(Parametros!$B:$B,MATCH("ahorro_laboral_monetizable_mes",Parametros!$A:$A,0))*IF(24<=4,0,IF(24=5,Parametros!$B$13,1))} -> 21914324194 | Z23: {=Z17-Z18-Z12-Z21-Z22+Z19+Z20+INDEX(Parametros!$B:$B,MATCH("ahorro_laboral_monetizable_mes",Parametros!$A:$A,0))*IF(25<=4,0,IF(25=5,Parametros!$B$13,1))} -> 19732756102 | AA23: {=AA17-AA18-AA12-AA21-AA22+AA19+AA20+INDEX(Parametros!$B:$B,MATCH("ahorro_laboral_monetizable_mes",Parametros!$A:$A,0))*IF(26<=4,0,IF(26=5,Parametros!$B$13,1))} -> 20351541569 | AB23: {=AB17-AB18-AB12-AB21-AB22+AB19+AB20+INDEX(Parametros!$B:$B,MATCH("ahorro_laboral_monetizable_mes",Parametros!$A:$A,0))*IF(27<=4,0,IF(27=5,Parametros!$B$13,1))} -> 21235247514 | AC23: {=AC17-AC18-AC12-AC21-AC22+AC19+AC20+INDEX(Parametros!$B:$B,MATCH("ahorro_laboral_monetizable_mes",Parametros!$A:$A,0))*IF(28<=4,0,IF(28=5,Parametros!$B$13,1))} -> 22570478440 | AD23: {=AD17-AD18-AD12-AD21-AD22+AD19+AD20+INDEX(Parametros!$B:$B,MATCH("ahorro_laboral_monetizable_mes",Parametros!$A:$A,0))*IF(29<=4,0,IF(29=5,Parametros!$B$13,1))} -> 21000006347 | AE23: {=AE17-AE18-AE12-AE21-AE22+AE19+AE20+INDEX(Parametros!$B:$B,MATCH("ahorro_laboral_monetizable_mes",Parametros!$A:$A,0))*IF(30<=4,0,IF(30=5,Parametros!$B$13,1))} -> 20486273696 | AF23: {=AF17-AF18-AF12-AF21-AF22+AF19+AF20+INDEX(Parametros!$B:$B,MATCH("ahorro_laboral_monetizable_mes",Parametros!$A:$A,0))*IF(31<=4,0,IF(31=5,Parametros!$B$13,1))} -> 20983178421 | AG23: {=AG17-AG18-AG12-AG21-AG22+AG19+AG20+INDEX(Parametros!$B:$B,MATCH("ahorro_laboral_monetizable_mes",Parametros!$A:$A,0))*IF(32<=4,0,IF(32=5,Parametros!$B$13,1))} -> 22085404516 | AH23: {=AH17-AH18-AH12-AH21-AH22+AH19+AH20+INDEX(Parametros!$B:$B,MATCH("ahorro_laboral_monetizable_mes",Parametros!$A:$A,0))*IF(33<=4,0,IF(33=5,Parametros!$B$13,1))} -> 25738555644 | AI23: {=AI17-AI18-AI12-AI21-AI22+AI19+AI20+INDEX(Parametros!$B:$B,MATCH("ahorro_laboral_monetizable_mes",Parametros!$A:$A,0))*IF(34<=4,0,IF(34=5,Parametros!$B$13,1))} -> 21140428621 | AJ23: {=AJ17-AJ18-AJ12-AJ21-AJ22+AJ19+AJ20+INDEX(Parametros!$B:$B,MATCH("ahorro_laboral_monetizable_mes",Parametros!$A:$A,0))*IF(35<=4,0,IF(35=5,Parametros!$B$13,1))} -> 19544223401 | AK23: {=AK17-AK18-AK12-AK21-AK22+AK19+AK20+INDEX(Parametros!$B:$B,MATCH("ahorro_laboral_monetizable_mes",Parametros!$A:$A,0))*IF(36<=4,0,IF(36=5,Parametros!$B$13,1))} -> 21914324194 | AL23: {=AL17-AL18-AL12-AL21-AL22+AL19+AL20+INDEX(Parametros!$B:$B,MATCH("ahorro_laboral_monetizable_mes",Parametros!$A:$A,0))*IF(37<=4,0,IF(37=5,Parametros!$B$13,1))} -> 19732756102 | AM23: {=AM17-AM18-AM12-AM21-AM22+AM19+AM20+INDEX(Parametros!$B:$B,MATCH("ahorro_laboral_monetizable_mes",Parametros!$A:$A,0))*IF(38<=4,0,IF(38=5,Parametros!$B$13,1))} -> 20351541569 | AN23: {=AN17-AN18-AN12-AN21-AN22+AN19+AN20+INDEX(Parametros!$B:$B,MATCH("ahorro_laboral_monetizable_mes",Parametros!$A:$A,0))*IF(39<=4,0,IF(39=5,Parametros!$B$13,1))} -> 21235247514 | AO23: {=AO17-AO18-AO12-AO21-AO22+AO19+AO20+INDEX(Parametros!$B:$B,MATCH("ahorro_laboral_monetizable_mes",Parametros!$A:$A,0))*IF(40<=4,0,IF(40=5,Parametros!$B$13,1))} -> 22570478440 | AP23: {=AP17-AP18-AP12-AP21-AP22+AP19+AP20+INDEX(Parametros!$B:$B,MATCH("ahorro_laboral_monetizable_mes",Parametros!$A:$A,0))*IF(41<=4,0,IF(41=5,Parametros!$B$13,1))} -> 21000006347 | AQ23: {=AQ17-AQ18-AQ12-AQ21-AQ22+AQ19+AQ20+INDEX(Parametros!$B:$B,MATCH("ahorro_laboral_monetizable_mes",Parametros!$A:$A,0))*IF(42<=4,0,IF(42=5,Parametros!$B$13,1))} -> 20486273696 | AR23: {=AR17-AR18-AR12-AR21-AR22+AR19+AR20+INDEX(Parametros!$B:$B,MATCH("ahorro_laboral_monetizable_mes",Parametros!$A:$A,0))*IF(43<=4,0,IF(43=5,Parametros!$B$13,1))} -> 20983178421 | AS23: {=AS17-AS18-AS12-AS21-AS22+AS19+AS20+INDEX(Parametros!$B:$B,MATCH("ahorro_laboral_monetizable_mes",Parametros!$A:$A,0))*IF(44<=4,0,IF(44=5,Parametros!$B$13,1))} -> 22085404516 | AT23: {=AT17-AT18-AT12-AT21-AT22+AT19+AT20+INDEX(Parametros!$B:$B,MATCH("ahorro_laboral_monetizable_mes",Parametros!$A:$A,0))*IF(45<=4,0,IF(45=5,Parametros!$B$13,1))} -> 25738555644 | AU23: {=AU17-AU18-AU12-AU21-AU22+AU19+AU20+INDEX(Parametros!$B:$B,MATCH("ahorro_laboral_monetizable_mes",Parametros!$A:$A,0))*IF(46<=4,0,IF(46=5,Parametros!$B$13,1))} -> 21140428621 | AV23: {=AV17-AV18-AV12-AV21-AV22+AV19+AV20+INDEX(Parametros!$B:$B,MATCH("ahorro_laboral_monetizable_mes",Parametros!$A:$A,0))*IF(47<=4,0,IF(47=5,Parametros!$B$13,1))} -> 19544223401 | AW23: {=AW17-AW18-AW12-AW21-AW22+AW19+AW20+INDEX(Parametros!$B:$B,MATCH("ahorro_laboral_monetizable_mes",Parametros!$A:$A,0))*IF(48<=4,0,IF(48=5,Parametros!$B$13,1))} -> 21914324194 | AX23: {=AX17-AX18-AX12-AX21-AX22+AX19+AX20+INDEX(Parametros!$B:$B,MATCH("ahorro_laboral_monetizable_mes",Parametros!$A:$A,0))*IF(49<=4,0,IF(49=5,Parametros!$B$13,1))} -> 19732756102 | AY23: {=AY17-AY18-AY12-AY21-AY22+AY19+AY20+INDEX(Parametros!$B:$B,MATCH("ahorro_laboral_monetizable_mes",Parametros!$A:$A,0))*IF(50<=4,0,IF(50=5,Parametros!$B$13,1))} -> 20351541569 | AZ23: {=AZ17-AZ18-AZ12-AZ21-AZ22+AZ19+AZ20+INDEX(Parametros!$B:$B,MATCH("ahorro_laboral_monetizable_mes",Parametros!$A:$A,0))*IF(51<=4,0,IF(51=5,Parametros!$B$13,1))} -> 21235247514 | BA23: {=BA17-BA18-BA12-BA21-BA22+BA19+BA20+INDEX(Parametros!$B:$B,MATCH("ahorro_laboral_monetizable_mes",Parametros!$A:$A,0))*IF(52<=4,0,IF(52=5,Parametros!$B$13,1))} -> 22570478440 | BB23: {=BB17-BB18-BB12-BB21-BB22+BB19+BB20+INDEX(Parametros!$B:$B,MATCH("ahorro_laboral_monetizable_mes",Parametros!$A:$A,0))*IF(53<=4,0,IF(53=5,Parametros!$B$13,1))} -> 21000006347 | BC23: {=BC17-BC18-BC12-BC21-BC22+BC19+BC20+INDEX(Parametros!$B:$B,MATCH("ahorro_laboral_monetizable_mes",Parametros!$A:$A,0))*IF(54<=4,0,IF(54=5,Parametros!$B$13,1))} -> 20486273696 | BD23: {=BD17-BD18-BD12-BD21-BD22+BD19+BD20+INDEX(Parametros!$B:$B,MATCH("ahorro_laboral_monetizable_mes",Parametros!$A:$A,0))*IF(55<=4,0,IF(55=5,Parametros!$B$13,1))} -> 20983178421 | BE23: {=BE17-BE18-BE12-BE21-BE22+BE19+BE20+INDEX(Parametros!$B:$B,MATCH("ahorro_laboral_monetizable_mes",Parametros!$A:$A,0))*IF(56<=4,0,IF(56=5,Parametros!$B$13,1))} -> 22085404516 | BF23: {=BF17-BF18-BF12-BF21-BF22+BF19+BF20+INDEX(Parametros!$B:$B,MATCH("ahorro_laboral_monetizable_mes",Parametros!$A:$A,0))*IF(57<=4,0,IF(57=5,Parametros!$B$13,1))} -> 25738555644 | BG23: {=BG17-BG18-BG12-BG21-BG22+BG19+BG20+INDEX(Parametros!$B:$B,MATCH("ahorro_laboral_monetizable_mes",Parametros!$A:$A,0))*IF(58<=4,0,IF(58=5,Parametros!$B$13,1))} -> 21140428621 | BH23: {=BH17-BH18-BH12-BH21-BH22+BH19+BH20+INDEX(Parametros!$B:$B,MATCH("ahorro_laboral_monetizable_mes",Parametros!$A:$A,0))*IF(59<=4,0,IF(59=5,Parametros!$B$13,1))} -> 19544223401 | BI23: {=BI17-BI18-BI12-BI21-BI22+BI19+BI20+INDEX(Parametros!$B:$B,MATCH("ahorro_laboral_monetizable_mes",Parametros!$A:$A,0))*IF(60<=4,0,IF(60=5,Parametros!$B$13,1))} -> 21914324194
A24: INCREMENTAL (proyecto − base)
A25: EBITDA incremental | B25: =B23-B14 -> 0 | C25: =C23-C14 -> 0 | D25: =D23-D14 -> 0 | E25: =E23-E14 -> 0 | F25: =F23-F14 -> 5.2145757e+08 | G25: =G23-G14 -> 776016769 | H25: =H23-H14 -> 7.9257968e+08 | I25: =I23-I14 -> 8.2950631e+08 | ... BI25: =BI23-BI14 -> 8.2377453e+08
A26: D&A (desde mes 5) | B26: =0 -> 0 | C26: =0 -> 0 | D26: =0 -> 0 | E26: =0 -> 0 | F26: =Dep_Amort!$D$10 -> 95119495 | G26: =Dep_Amort!$D$10 -> 95119495 | H26: =Dep_Amort!$D$10 -> 95119495 | I26: =Dep_Amort!$D$10 -> 95119495 | J26: =Dep_Amort!$D$10 -> 95119495 | K26: =Dep_Amort!$D$10 -> 95119495 | L26: =Dep_Amort!$D$10 -> 95119495 | M26: =Dep_Amort!$D$10 -> 95119495 | ... BI26: =Dep_Amort!$D$10 -> 95119495
A27: EBIT incremental | B27: =B25-B26 -> 0 | C27: =C25-C26 -> 0 | D27: =D25-D26 -> 0 | E27: =E25-E26 -> 0 | F27: =F25-F26 -> 4.2633807e+08 | G27: =G25-G26 -> 680897274 | H27: =H25-H26 -> 6.9746018e+08 | I27: =I25-I26 -> 7.3438682e+08 | ... BI27: =BI25-BI26 -> 7.2865504e+08
A28: Impuesto de renta (35%) | B28: =MAX(0,B27)*Parametros!$B$8 -> 0 | C28: =MAX(0,C27)*Parametros!$B$8 -> 0 | D28: =MAX(0,D27)*Parametros!$B$8 -> 0 | E28: =MAX(0,E27)*Parametros!$B$8 -> 0 | F28: =MAX(0,F27)*Parametros!$B$8 -> 1.4921832e+08 | G28: =MAX(0,G27)*Parametros!$B$8 -> 2.3831405e+08 | H28: =MAX(0,H27)*Parametros!$B$8 -> 2.4411106e+08 | I28: =MAX(0,I27)*Parametros!$B$8 -> 2.5703539e+08 | ... BI28: =MAX(0,BI27)*Parametros!$B$8 -> 2.5502926e+08
A29: Utilidad neta incremental | B29: =B27-B28 -> 0 | C29: =C27-C28 -> 0 | D29: =D27-D28 -> 0 | E29: =E27-E28 -> 0 | F29: =F27-F28 -> 2.7711975e+08 | G29: =G27-G28 -> 4.4258323e+08 | H29: =H27-H28 -> 4.5334912e+08 | I29: =I27-I28 -> 4.7735143e+08 | ... BI29: =BI27-BI28 -> 4.7362577e+08

Sheet CAPEX
A1: CAPEX ULOGIX — L1 / L2 / L3 + infraestructura transversal
A2: Fuente viva del ERP. Cantidad y costo unitario son entradas editables; CAPEX COP, subtotales y total son fórmulas. Licencias perpetuas vienen de la hoja Licencias.
A4: seccion | B4: linea | C4: activo / paquete | D4: cant. | E4: moneda | F4: costo unitario | G4: CAPEX COP | H4: vida (años) | I4: categoria D&A
C5: ▍ L1 — COCA-COLA 350 ml · VIDRIO RETORNABLE
A6: Maquinaria usada | B6: L1 | C6: Llenadora/tapadora KRONES usada 44.000 bph (VODM/Modulfill; reserva RFQ) | D6: 1 | E6: USD | F6: 550000 | G6: {=IF($E6="COP",$D6*$F6,IF($E6="USD*",$D6*$F6*Parametros!$B$5,IF($E6="GBP*",$D6*$F6*INDEX(Parametros!$B:$B,MATCH("gbp_cop",Parametros!$A:$A,0)),$D6*$F6*Parametros!$B$5*Parametros!$B$6)))} -> 1733272145 | H6: 10 | I6: equipos
A7: Maquinaria usada | B7: L1 | C7: Conveyors, motores y VFD para llenado y encajonado | D7: 1 | E7: USD | F7: 100000 | G7: {=IF($E7="COP",$D7*$F7,IF($E7="USD*",$D7*$F7*Parametros!$B$5,IF($E7="GBP*",$D7*$F7*INDEX(Parametros!$B:$B,MATCH("gbp_cop",Parametros!$A:$A,0)),$D7*$F7*Parametros!$B$5*Parametros!$B$6)))} -> 315140390 | H7: 7 | I7: equipos
A8: Diseño ULogix | B8: L1 | C8: Encajonadora custom para canastilla 30x30 (BOM de ingenieria; reserva RFQ) | D8: 1 | E8: USD | F8: 60000 | G8: {=IF($E8="COP",$D8*$F8,IF($E8="USD*",$D8*$F8*Parametros!$B$5,IF($E8="GBP*",$D8*$F8*INDEX(Parametros!$B:$B,MATCH("gbp_cop",Parametros!$A:$A,0)),$D8*$F8*Parametros!$B$5*Parametros!$B$6)))} -> 189084234 | H8: 10 | I8: automatizacion
A9: Benchmark retrofit | B9: L1 | C9: Upgrade lavadora retornable / prewash (KRONES Lavatec) | D9: 0 | E9: USD | F9: 450000 | G9: {=IF($E9="COP",$D9*$F9,IF($E9="USD*",$D9*$F9*Parametros!$B$5,IF($E9="GBP*",$D9*$F9*INDEX(Parametros!$B:$B,MATCH("gbp_cop",Parametros!$A:$A,0)),$D9*$F9*Parametros!$B$5*Parametros!$B$6)))} -> 0 | H9: 10 | I9: equipos
A10: Benchmark retrofit | B10: L1 | C10: Inspeccion envase vacio (HEUFT SPECTRUM II SX) | D10: 0 | E10: USD | F10: 180000 | G10: {=IF($E10="COP",$D10*$F10,IF($E10="USD*",$D10*$F10*Parametros!$B$5,IF($E10="GBP*",$D10*$F10*INDEX(Parametros!$B:$B,MATCH("gbp_cop",Parametros!$A:$A,0)),$D10*$F10*Parametros!$B$5*Parametros!$B$6)))} -> 0 | H10: 7 | I10: automatizacion
A11: Benchmark retrofit | B11: L1 | C11: Etiquetadora y sincronizacion (servos) | D11: 0 | E11: USD | F11: 120000 | G11: {=IF($E11="COP",$D11*$F11,IF($E11="USD*",$D11*$F11*Parametros!$B$5,IF($E11="GBP*",$D11*$F11*INDEX(Parametros!$B:$B,MATCH("gbp_cop",Parametros!$A:$A,0)),$D11*$F11*Parametros!$B$5*Parametros!$B$6)))} -> 0 | H11: 7 | I11: automatizacion
C12: Subtotal — L1 — COCA-COLA 350 ml · VIDRIO RETORNABLE | G12: =SUM(G6:G11) -> 2237496769
C14: ▍ L2 — QuAtro 1,5 L · PET
A15: Maquinaria usada | B15: L2 | C15: Llenadora KRONES usada CSD PET 18.000 bph (Mecafill/Contiform; reserva RFQ) | D15: 1 | E15: USD | F15: 425000 | G15: {=IF($E15="COP",$D15*$F15,IF($E15="USD*",$D15*$F15*Parametros!$B$5,IF($E15="GBP*",$D15*$F15*INDEX(Parametros!$B:$B,MATCH("gbp_cop",Parametros!$A:$A,0)),$D15*$F15*Parametros!$B$5*Parametros!$B$6)))} -> 1339346658 | H15: 10 | I15: equipos
A16: Maquinaria usada | B16: L2 | C16: KRONES Variopac 459 usada para termoencogible (Machinio) | D16: 1 | E16: USD* | F16: 79900 | G16: {=IF($E16="COP",$D16*$F16,IF($E16="USD*",$D16*$F16*Parametros!$B$5,IF($E16="GBP*",$D16*$F16*INDEX(Parametros!$B:$B,MATCH("gbp_cop",Parametros!$A:$A,0)),$D16*$F16*Parametros!$B$5*Parametros!$B$6)))} -> 259584713 | H16: 7 | I16: equipos
A17: Maquinaria usada | B17: L2 | C17: Conveyors / transporte PET y enlace al GANTRY compartido | D17: 1 | E17: USD | F17: 90000 | G17: {=IF($E17="COP",$D17*$F17,IF($E17="USD*",$D17*$F17*Parametros!$B$5,IF($E17="GBP*",$D17*$F17*INDEX(Parametros!$B:$B,MATCH("gbp_cop",Parametros!$A:$A,0)),$D17*$F17*Parametros!$B$5*Parametros!$B$6)))} -> 283626351 | H17: 10 | I17: equipos
A18: Benchmark retrofit | B18: L2 | C18: Inspeccion botella llena (HEUFT PRIME) | D18: 0 | E18: USD | F18: 160000 | G18: {=IF($E18="COP",$D18*$F18,IF($E18="USD*",$D18*$F18*Parametros!$B$5,IF($E18="GBP*",$D18*$F18*INDEX(Parametros!$B:$B,MATCH("gbp_cop",Parametros!$A:$A,0)),$D18*$F18*Parametros!$B$5*Parametros!$B$6)))} -> 0 | H18: 7 | I18: automatizacion
C19: Subtotal — L2 — QuAtro 1,5 L · PET | G19: =SUM(G15:G18) -> 1882557722
C21: ▍ L1-L2 — GANTRY DE PALETIZADO COMPARTIDO
A22: Celdas roboticas (BOM real) | B22: L1-L2 | C22: Servomotor MU 300 (ABB) | D22: 1 | E22: USD* | F22: 2800 | G22: {=IF($E22="COP",$D22*$F22,IF($E22="USD*",$D22*$F22*Parametros!$B$5,IF($E22="GBP*",$D22*$F22*INDEX(Parametros!$B:$B,MATCH("gbp_cop",Parametros!$A:$A,0)),$D22*$F22*Parametros!$B$5*Parametros!$B$6)))} -> 9096836 | H22: 10 | I22: equipos
A23: Celdas roboticas (BOM real) | B23: L1-L2 | C23: Servomotor MU 200 (ABB) | D23: 1 | E23: USD* | F23: 2000 | G23: {=IF($E23="COP",$D23*$F23,IF($E23="USD*",$D23*$F23*Parametros!$B$5,IF($E23="GBP*",$D23*$F23*INDEX(Parametros!$B:$B,MATCH("gbp_cop",Parametros!$A:$A,0)),$D23*$F23*Parametros!$B$5*Parametros!$B$6)))} -> 6497740 | H23: 10 | I23: equipos
A24: Celdas roboticas (BOM real) | B24: L1-L2 | C24: Controlador IRC5 (ABB) - cotizacion IGAM, envio/logistica incluidos | D24: 1 | E24: USD* | F24: 6500 | G24: {=IF($E24="COP",$D24*$F24,IF($E24="USD*",$D24*$F24*Parametros!$B$5,IF($E24="GBP*",$D24*$F24*INDEX(Parametros!$B:$B,MATCH("gbp_cop",Parametros!$A:$A,0)),$D24*$F24*Parametros!$B$5*Parametros!$B$6)))} -> 21117655 | H24: 10 | I24: equipos
A25: Celdas roboticas (BOM real) | B25: L1-L2 | C25: Reductor AB115-005-S2-P2 (Apex Dynamics) | D25: 1 | E25: USD* | F25: 1100 | G25: {=IF($E25="COP",$D25*$F25,IF($E25="USD*",$D25*$F25*Parametros!$B$5,IF($E25="GBP*",$D25*$F25*INDEX(Parametros!$B:$B,MATCH("gbp_cop",Parametros!$A:$A,0)),$D25*$F25*Parametros!$B$5*Parametros!$B$6)))} -> 3573757 | H25: 10 | I25: equipos
A26: Celdas roboticas (BOM real) | B26: L1-L2 | C26: Eje lineal Rexroth_CKK280_S2200 (Bosch-Rexroth) | D26: 1 | E26: USD* | F26: 5500 | G26: {=IF($E26="COP",$D26*$F26,IF($E26="USD*",$D26*$F26*Parametros!$B$5,IF($E26="GBP*",$D26*$F26*INDEX(Parametros!$B:$B,MATCH("gbp_cop",Parametros!$A:$A,0)),$D26*$F26*Parametros!$B$5*Parametros!$B$6)))} -> 17868785 | H26: 10 | I26: equipos
A27: Celdas roboticas (BOM real) | B27: L1-L2 | C27: Eje lineal Rexroth_CKR280_S4600 (Bosch-Rexroth) | D27: 1 | E27: USD* | F27: 7500 | G27: {=IF($E27="COP",$D27*$F27,IF($E27="USD*",$D27*$F27*Parametros!$B$5,IF($E27="GBP*",$D27*$F27*INDEX(Parametros!$B:$B,MATCH("gbp_cop",Parametros!$A:$A,0)),$D27*$F27*Parametros!$B$5*Parametros!$B$6)))} -> 24366525 | H27: 10 | I27: equipos
A28: Celdas roboticas (BOM real) | B28: L1-L2 | C28: Acople ACP001 (Manufacturado) | D28: 1 | E28: USD* | F28: 450 | G28: {=IF($E28="COP",$D28*$F28,IF($E28="USD*",$D28*$F28*Parametros!$B$5,IF($E28="GBP*",$D28*$F28*INDEX(Parametros!$B:$B,MATCH("gbp_cop",Parametros!$A:$A,0)),$D28*$F28*Parametros!$B$5*Parametros!$B$6)))} -> 1461991.5 | H28: 10 | I28: equipos
A29: Celdas roboticas (BOM real) | B29: L1-L2 | C29: Perfil de soporte gantry SP001 (Manufacturado) | D29: 2 | E29: USD* | F29: 1200 | G29: {=IF($E29="COP",$D29*$F29,IF($E29="USD*",$D29*$F29*Parametros!$B$5,IF($E29="GBP*",$D29*$F29*INDEX(Parametros!$B:$B,MATCH("gbp_cop",Parametros!$A:$A,0)),$D29*$F29*Parametros!$B$5*Parametros!$B$6)))} -> 7797288 | H29: 10 | I29: equipos
A30: Celdas roboticas (BOM real) | B30: L1-L2 | C30: Gripper neumatico GRP001 4 mordazas 40 kg (Manufacturado) | D30: 1 | E30: USD* | F30: 9000 | G30: {=IF($E30="COP",$D30*$F30,IF($E30="USD*",$D30*$F30*Parametros!$B$5,IF($E30="GBP*",$D30*$F30*INDEX(Parametros!$B:$B,MATCH("gbp_cop",Parametros!$A:$A,0)),$D30*$F30*Parametros!$B$5*Parametros!$B$6)))} -> 29239830 | H30: 10 | I30: equipos
A31: Celdas roboticas (BOM real) | B31: L1-L2 | C31: Cilindro neumatico DSBC-80-150-PPSA-N3 (Festo) | D31: 8 | E31: USD* | F31: 220 | G31: {=IF($E31="COP",$D31*$F31,IF($E31="USD*",$D31*$F31*Parametros!$B$5,IF($E31="GBP*",$D31*$F31*INDEX(Parametros!$B:$B,MATCH("gbp_cop",Parametros!$A:$A,0)),$D31*$F31*Parametros!$B$5*Parametros!$B$6)))} -> 5718011.2 | H31: 10 | I31: equipos
A32: Celdas roboticas (BOM real) | B32: L1-L2 | C32: Valvula antirretorno HGL-3/8-QS-8 (Festo) | D32: 8 | E32: USD* | F32: 55 | G32: {=IF($E32="COP",$D32*$F32,IF($E32="USD*",$D32*$F32*Parametros!$B$5,IF($E32="GBP*",$D32*$F32*INDEX(Parametros!$B:$B,MATCH("gbp_cop",Parametros!$A:$A,0)),$D32*$F32*Parametros!$B$5*Parametros!$B$6)))} -> 1429502.8 | H32: 10 | I32: equipos
A33: Celdas roboticas (BOM real) | B33: L1-L2 | C33: Electrovalvula VUVS-L30-B52-D-G38-F8-1B2 (Festo) | D33: 1 | E33: USD* | F33: 220 | G33: {=IF($E33="COP",$D33*$F33,IF($E33="USD*",$D33*$F33*Parametros!$B$5,IF($E33="GBP*",$D33*$F33*INDEX(Parametros!$B:$B,MATCH("gbp_cop",Parametros!$A:$A,0)),$D33*$F33*Parametros!$B$5*Parametros!$B$6)))} -> 714751.4 | H33: 10 | I33: equipos
... A57: Celdas roboticas (BOM real) | B57: L1-L2 | C57: HMI CP620 (ABB) | D57: 1 | E57: USD* | F57: 650 | G57: {=IF($E57="COP",$D57*$F57,IF($E57="USD*",$D57*$F57*Parametros!$B$5,IF($E57="GBP*",$D57*$F57*INDEX(Parametros!$B:$B,MATCH("gbp_cop",Parametros!$A:$A,0)),$D57*$F57*Parametros!$B$5*Parametros!$B$6)))} -> 2111765.5 | H57: 10 | I57: equipos
C58: Subtotal — L1-L2 — GANTRY DE PALETIZADO COMPARTIDO | G58: =SUM(G22:G57) -> 3.1349321e+08
C60: ▍ L3 — GARRAFÓN 25 L · LLENADORA EXISTENTE
A61: Celdas roboticas (BOM real) | B61: L3 | C61: Robot ABB para garrafones - cotizacion EUROBOTS, envio/logistica incluidos | D61: 1 | E61: GBP* | F61: 13500 | G61: {=IF($E61="COP",$D61*$F61,IF($E61="USD*",$D61*$F61*Parametros!$B$5,IF($E61="GBP*",$D61*$F61*INDEX(Parametros!$B:$B,MATCH("gbp_cop",Parametros!$A:$A,0)),$D61*$F61*Parametros!$B$5*Parametros!$B$6)))} -> 59899500 | H61: 10 | I61: equipos
A62: Celdas roboticas (BOM real) | B62: L3 | C62: Controlador del robot (incluido en paquete EUROBOTS; no duplicar) | D62: 0 | E62: USD* | F62: 22000 | G62: {=IF($E62="COP",$D62*$F62,IF($E62="USD*",$D62*$F62*Parametros!$B$5,IF($E62="GBP*",$D62*$F62*INDEX(Parametros!$B:$B,MATCH("gbp_cop",Parametros!$A:$A,0)),$D62*$F62*Parametros!$B$5*Parametros!$B$6)))} -> 0 | H62: 10 | I62: equipos
A63: Celdas roboticas (BOM real) | B63: L3 | C63: Transportador PM 9710 (Interroll) | D63: 5 | E63: USD* | F63: 5500 | G63: {=IF($E63="COP",$D63*$F63,IF($E63="USD*",$D63*$F63*Parametros!$B$5,IF($E63="GBP*",$D63*$F63*INDEX(Parametros!$B:$B,MATCH("gbp_cop",Parametros!$A:$A,0)),$D63*$F63*Parametros!$B$5*Parametros!$B$6)))} -> 89343925 | H63: 10 | I63: equipos
A64: Celdas roboticas (BOM real) | B64: L3 | C64: Gripper neumatico GRP001 3 ventosas 15.5 kg (Manufacturado) | D64: 1 | E64: USD* | F64: 4500 | G64: {=IF($E64="COP",$D64*$F64,IF($E64="USD*",$D64*$F64*Parametros!$B$5,IF($E64="GBP*",$D64*$F64*INDEX(Parametros!$B:$B,MATCH("gbp_cop",Parametros!$A:$A,0)),$D64*$F64*Parametros!$B$5*Parametros!$B$6)))} -> 14619915 | H64: 10 | I64: equipos
A65: Celdas roboticas (BOM real) | B65: L3 | C65: Generador de vacio OVEM-14-L-B-QO-CE-N-1P (Festo) | D65: 3 | E65: USD* | F65: 320 | G65: {=IF($E65="COP",$D65*$F65,IF($E65="USD*",$D65*$F65*Parametros!$B$5,IF($E65="GBP*",$D65*$F65*INDEX(Parametros!$B:$B,MATCH("gbp_cop",Parametros!$A:$A,0)),$D65*$F65*Parametros!$B$5*Parametros!$B$6)))} -> 3118915.2 | H65: 10 | I65: equipos
A66: Celdas roboticas (BOM real) | B66: L3 | C66: Acumulador de vacio CRVZS-0.1 (Festo) | D66: 3 | E66: USD* | F66: 45 | G66: {=IF($E66="COP",$D66*$F66,IF($E66="USD*",$D66*$F66*Parametros!$B$5,IF($E66="GBP*",$D66*$F66*INDEX(Parametros!$B:$B,MATCH("gbp_cop",Parametros!$A:$A,0)),$D66*$F66*Parametros!$B$5*Parametros!$B$6)))} -> 438597.45 | H66: 10 | I66: equipos
A67: Celdas roboticas (BOM real) | B67: L3 | C67: Filtro de vacio VAF-PK-6 (Festo) | D67: 3 | E67: USD* | F67: 55 | G67: {=IF($E67="COP",$D67*$F67,IF($E67="USD*",$D67*$F67*Parametros!$B$5,IF($E67="GBP*",$D67*$F67*INDEX(Parametros!$B:$B,MATCH("gbp_cop",Parametros!$A:$A,0)),$D67*$F67*Parametros!$B$5*Parametros!$B$6)))} -> 536063.55 | H67: 10 | I67: equipos
...

Sheet Proveedores_CAPEX
A1: PROVEEDORES Y FUENTES DEL CAPEX — registro de procura
A2: Los valores 'cotizacion usuario' incluyen la logistica indicada. Los benchmarks usados requieren inspeccion, RFQ y validacion de formato/voltaje antes de adjudicar.
A4: linea | B4: equipo / alcance | C4: proveedor | D4: tipo_fuente | E4: valor | F4: moneda | G4: logistica | H4: capacidad / criterio | I4: url / referencia | J4: estado
A5: L3 | B5: Robot ABB celda garrafones | C5: EUROBOTS | D5: Cotizacion informada por propietario | E5: 13500 | F5: GBP | G5: Envio y logistica incluidos | H5: Llenadora existente 600 gfn/h; robot elimina cuello manual | I5: Cotizacion directa; solicitar PDF y seriales | J5: Seleccionado / validar alcance del controlador
A6: L1-L2 | B6: Controlador ABB IRC5 GANTRY compartido | C6: IGAM | D6: Cotizacion informada por propietario | E6: 6500 | F6: USD | G6: Envio y logistica incluidos | H6: Un controlador para celda compartida y alternada L1/L2 | I6: Cotizacion directa; solicitar PDF | J6: Seleccionado
A7: L2 | B7: KRONES Variopac 459 usada | C7: Machinio / vendedor Chicago | D7: Listado publico usado | E7: 79900 | F7: USD | G7: No confirmada | H7: 28-30 paquetes/min; formatos hasta 1,5 L | I7: https://www.machinio.com/cat/variopac | J7: Benchmark con precio; RFQ pendiente
A8: L2 | B8: KRONES Variopac Pro TFS-4-DS 2021 | C8: MachinePoint | D8: Listado publico usado | E8: Precio a consultar | F8: USD/EUR | G8: Servicios de transporte disponibles | H8: 45 paquetes/min; 1.200 h | I8: https://www.machinepoint.com/machinepoint/inventory.nsf/idmaquina/300047107?ln=es&opendocument= | J8: Alternativa RFQ
